Workbook
Name \0: #REF!
Name \0: #REF!
Name \0: #REF!
Name \a: #N/A
Name \c: [1]Plan2!#REF!
Name \c: [1]Plan2!#REF!
Name \c: [1]Plan2!#REF!
Name \p: [1]Plan2!#REF!
Name \p: [1]Plan2!#REF!
Name \p: [1]Plan2!#REF!
Name \Q: #REF!
Name \Q: #REF!
Name \Q: #REF!
Name \Z: #REF!
Name \Z: #REF!
Name \Z: #REF!
Name ______R: #REF!
Name ______R: #REF!
Name ______R: #REF!
Name _____R: #REF!
Name _____R: #REF!
Name _____R: #REF!
Name ____R: #REF!
Name ____R: #REF!
Name ____R: #REF!
Name ____VB6: #REF!
Name ____VB6: #REF!
Name ____VB6: #REF!
Name ___R: '[2]Solo I'!#REF!
Name ___R: '[2]Solo I'!#REF!
Name ___R: '[2]Solo I'!#REF!
Name ___VB6: #REF!
Name ___VB6: #REF!
Name ___VB6: #REF!
Name __EQP1: #REF!
Name __EQP2: #REF!
Name __EQP3: #REF!
Name __EQP4: #REF!
Name __EQP5: #REF!
Name __EQP6: #REF!
Name __R: '[2]Solo I'!#REF!
Name __R: '[2]Solo I'!#REF!
Name __R: '[2]Solo I'!#REF!
Name __VB6: #REF!
Name __VB6: #REF!
Name __VB6: #REF!
Name _1: #N/A
Name _1____MÃO_DE_OBRA_DIRETA: '[3]-01-MOD'!$A$1
Name _11: #N/A
Name _13.1___MATERIAL_CONSUMO: '[3]13-MAT-FERR'!$A$2
Name _13.2___MATERIAL_APLICAÇÃO: '[3]13-MAT-FERR'!$A$5
Name _13.3__FERRAMENTAS: '[3]13-MAT-FERR'!$A$39
Name _13____MATERIAIS_E_FERRAMENTAS: '[3]13-MAT-FERR'!$A$1
Name _14____MATERIAL_DE_SEGURANÇA: '[3]14-MAT.SEG '!$A$1
Name _15____DIVERSOS: '[3]15-DIVERSOS'!$A$1
Name _16.1___EQUIPAMENTOS_MAIORES: '[3]16-EQUIP.'!$A$4
Name _16.2___EQUIPAMENTOS_MENORES: '[3]16-EQUIP.'!$A$53
Name _16.3___VEÍCULOS: '[4]16-EQUIP.'!#REF!
Name _16.3___VEÍCULOS: '[4]16-EQUIP.'!#REF!
Name _16.3___VEÍCULOS: '[4]16-EQUIP.'!#REF!

Sheet Capa
A2: Lista de Cargas | BA2: PBC-LC-25E-0001
A4: Projeto N°: PBC-001-25E-0001 | BA4: Projeto: Banco de Capacitor
A17: Lista de Cargas
A35: 1 | D35: 10/05/2025 | J35: EALB | P35: EALB | V35: DFER | AB35: Aprovado
A36: 0 | D36: 08/04/2025 | J36: EALB | P36: EALB | V36: DFER | AB36: Para Comentários
A37: Rev. | D37: Data | J37: Elaborado | P37: Revisado | V37: Aprovado | AB37: Propósito da Emissão

Sheet Referências e Notas
A2: Lista de Cargas | G2: PBC-LC-25E-0001
A4: Projeto N°: PBC-001-25E-0001 | G4: Projeto: Banco de Capacitor
A6: NOTAS:
A8: 1 - NESSA LISTA OS EQUIPAMENTOS FUTUROS NÃO FORAM CONSIDERADOS;
A9: 2 - FATOR DE DEMANDA APLICADO PARA TODOS OS EQUIPAMENTOS DE PROCESSOS: 60%;
A10: 3 - OS QUADROS DE DISTRIBUIÇÃO DE FORÇA (QDF) INDICADOS NESSA LISTA, ALIMENTAM ALÉM DA CARGAS TERMINAIS, OUTROS QUADROS COMO OS DE DISTRIBUIÇÃO DE FORÇA E ILUMINAÇÃO (QDFL), PARA DETALHES DE CARGAS, DEVERÁ SE CONSULTADOS OS DIAGRAMAS UNIFILARES CORRESPONDENTE A CADA QUADRO;
A13: 4 - O PAINEL DE MÉDIA TENSÃO DEVE ESTAR EM CONFORMIDADE COM A NORMA ABNT NBR IEC 62271-200 E A ABNT NBR 14039;
A15: 5 - OS PAINÉIS DE BAIXA TENSÃO DEVERÃO ESTAR EM CONFORMIDADE COM A NORMA ABNT NBR IEC 61439:2016, BEM COMO NR-10 E NR-12;
A17: 6 - DEVERÁ SER PREVISTO UM BANCO DE CAPACITOR PARA CORRIGIR O FATOR DE POTÊNCIA DA INSTALAÇÃO E LIBERAR POTÊNCIA DO TRANSFORMADOR;
A19: 7 - PARA DIAGRAMA UNIFILAR VER DOCUMENTO: UN-PBC-25E-0001.
A22: REFERÊNCIAS:
A24: 1 - ABNT – Associação Brasileira De Normas Técnicas. NBR 5410: Instalações Elétricas de Baixa Tensão. Rio de Janeiro: ABNT, 2004. 209 p. 2 - ABNT – Associação Brasileira de Normas Técnicas. NBR 5419: Proteção contra descargas atmosféricas. Rio de Janeiro: ABNT, 2015. 3 - ABNT – Associação Brasileira De Normas Técnicas. NBR IEC 61439-1: Conjuntos de manobra e controle de baixa tensão - Parte 1: Regras gerais. Rio de Janeiro: ABNT, 2016. 147 p. 4 - ABNT – Associação Brasileira De Normas Técnicas. NBR IEC 61439-2: Conjuntos de manobra e controle de baixa tensão - Parte 2: Requisitos para conjuntos de manobra e controle de baixa tensão. Rio de Janeiro: ABNT, 2016. 22 p. 5 - ABNT. Associação Brasileira de Normas Técnicas. ABNT NBR IEC 60947-2: Aparelhos de manobra e comando de baixa tensão – Parte 2: Disjuntores. Rio de Janeiro, 2011. 6 - ANEEL – Agência Nacional de Energia Elétrica. Resolução Normativa ANEEL nº 1000. Brasília, ANEEL, 2021. 7 - Ministério do Trabalho e Emprego. NR 10: Segurança em Instalações e Serviços em Eletricidade. Brasília: Ministério do Trabalho e Emprego, 2019. 8 - Ministério do Trabalho e Emprego. NR 12: Segurança no Trabalho em Máquinas e Equipamentos. Brasília: Ministério do Trabalho e Emprego, 2019.
A48: RESUMO DAS CARGAS:
A50: Descrição | B50: Fator de Potência Atual | C50: Potência Ativa Demandada (kW) | D50: Potência Aparente Demandada (kVA) | E50: Potência Reativa Demandada (kVAr) | F50: Corrente Nominal Demandada (A) | G50: Carregamento do Trafo (%)
A52: TRAFO-001 | B52: ='Lista de Carga'!P130 -> 0.8650532 | C52: - | G52: 1
A53: QGBT-001 | C53: ='Lista de Carga'!S130 -> 852.82242 | D53: ='Lista de Carga'!U130 -> 985.86125 | E53: ='Lista de Carga'!T130 -> 494.58701 | F53: ='Lista de Carga'!V130 -> 1497.8612 | G53: =SUM('Lista de Carga'!Y17:Y129) -> 0.98874214
A54: RESERVA (10%) | C54: ='Lista de Carga'!S131 -> 85.282242 | D54: ='Lista de Carga'!U131 -> 98.586125 | E54: ='Lista de Carga'!T131 -> 49.458701 | F54: ='Lista de Carga'!V131 -> 149.78612 | G54: =G52*0.1 -> 0.1
A55: TOTAL | C55: =C53+C54 -> 938.10467 | D55: =D53+D54 -> 1084.4474 | E55: =E53+E54 -> 544.04571 | F55: =F53+F54 -> 1647.6473 | G55: =G53+G54 -> 1.0887421

Sheet Lista de Cargas
A2: Revisão | B2: Painel | C2: Tag No. | G2: Pavimento | H2: Sistema | I2: Painel de Origem | J2: Descrição / Área | K2: Função | L2: Capacidade | M2: Unidade | N2: Tensão (V) | O2: Potência Nominal do Equipamento (kW) | P2: Potência Nominal Instalada (kW) | Q2: Potência Nominal Aparente (kVA) | R2: Potência Demandada em Operação (kW) | S2: Potência Demandada em Operação (kVA) | T2: Fases | U2: Diversidade | V2: Cos (φ) | W2: Eficiência | X2: Fator de Demanda | Y2: Novo (N) Futuro (F) Existente (E) | Z2: Operação (horas por dia) | AA2: Consumo de Energia (kWh) | AB2: Normal (-) Gerador e NoBreak(GE+NB) | AC2: Corrente (A) | AF2: 440 V | AG2: 380 V | AV2: Electrical Data | BC2: AUTOMATICO | BJ2: MANUAL
C3: Bloco de Produção | D3: Linha de Processo | E3: Tipo de Equip. | F3: Sequencial | AD3: circuito | AE3: Cabo | AH3: 220 V | AI3: 127 V | AJ3: GE 440 V | AK3: GE 380 V | AL3: GE 220 V | AM3: GE 127 V | AN3: NBL 440 V | AO3: NBL 380 V | AP3: NBL 220 V | AQ3: NBL 127 V | AR3: NB 440 V | AS3: NB 380 V | AT3: NB 220 V | AU3: NB 127 V | AV3: Nominal Power (kW) | AW3: Phase | AX3: Voltage (V) | AY3: Concessionária (-) Gerador (GE) No Break (NB) | AZ3: Painel (P) CCM (D) Tomada (T) | BA3: Vel.Variavel (S/N) | BB3: Novo(N) Futuro (F) Existente (E) | BC3: Relé/Inversor | BD3: Vem com controle de partida (S/N) | BE3: Motor (S/N) | BF3: Bomba Porte (S/N) | BG3: FP CALC (A/M) | BH3: Rendimento | BI3: FP | BJ3: FP
A4: 02 | B4: QDNO-397 | C4: - | D4: - | E4: CB | F4: 001 | G4: T | H4: PR | I4: PNBT-02 | J4: Sala de Pesagem - 0165.4.02 | K4: Cabine de Pesagem | L4: - | M4: - | N4: =AX4 -> 440 | O4: 20 | P4: =AV4 -> 20 | Q4: =P4/V4/W4 -> 25 | R4: =P4*U4*X4 -> 14 | S4: =Q4*U4*X4 -> 17.5 | T4: =AW4 -> 3 | U4: 1 | V4: =IF((BE4="N")*AND(BG4="M"),BJ4,BI4) -> 0.8 | W4: =IF(BE4="N",1,BH4/100) -> 1 | X4: 0.7 | Y4: =BB4 -> N | Z4: 24 | AA4: =Z4*R4 -> 336 | AB4: =AY4 -> NB | AC4: =IF((((T4=3))),(Q4*1000)/((SQRT(3)*N4)),(IF(((T4=1)),(Q4*1000)/((N4)),(IF(((T4=2)),(Q4*1000)/((N4)),0))))) -> 32.803993 | AF4: =IF(AND($AX4=440,$AB4="-"),$S4," ") | AG4: =IF(AND($AX4=380,$AB4="-"),$S4," ") | AH4: =IF(AND($AX4=220,$AB4="-"),$S4," ") | AI4: =IF(AND($AX4=127,$AB4="-"),$S4," ") | AJ4: =IF(AND($AX4=440,$AB4="GE"),$S4," ") | AK4: =IF(AND($AX4=380,$AB4="GE"),$S4," ") | AL4: =IF(AND($AX4=220,$AB4="GE"),$S4," ") | AM4: =IF(AND($AX4=127,$AB4="GE"),$S4," ") | AN4: =IF(AND($AX4=440,$AB4="GE+NBL"),$S4," ") | AO4: =IF(AND($AX4=380,$AB4="GE+NBL"),$S4," ") | AP4: =IF(AND($AX4=220,$AB4="GE+NBL"),$S4," ") | AQ4: =IF(AND($AX4=127,$AB4="GE+NBL"),$S4," ") | AR4: =IF(AND($AX4=440,$AB4="GE+NB"),$S4," ") | AS4: =IF(AND($AX4=380,$AB4="GE+NB"),$S4," ") | AT4: =IF(AND($AX4=220,$AB4="GE+NB"),$S4," ") | AU4: =IF(AND($AX4=127,$AB4="GE+NB"),$S4," ") | AV4: 20 | AW4: 3 | AX4: 440 | AY4: NB | AZ4: P | BA4: N | BB4: N | BC4: =IF(((AZ4="P")*AND(BA4="N")*AND(BF4="S")*AND(BE4="S")*AND(BD4="N")*AND(AV4<=3.68)),"RELÉ",(IF(((AZ4="P")*AND(BA4="N")*AND(BE4="S")*AND(BD4="S")),"C-FORNECIDO",(IF(((AZ4="P")*AND(BA4="S")*AND(BD4="S")),"C-FORNECIDO",(IF(((AZ4="D")*AND(BA4="S")*AND(BD4="N")),"I-PROJETAR",(IF(((AZ4="P")*AND(BA4="N")*AND(BE4="S")*AND(AV4>=3.68)*AND(BD4="N")),"I-PROJETAR",(IF(((AZ4="D")*AND(BA4="N")*AND(BE4="S")*AND(AV4<=3.68)*AND(BD4="N")),"DIRETA",(IF(((AZ4="D")*AND(BA4="N")*AND(BE4="S")*AND(AV4>=3.68)*AND(BD4="N")),"I-PROJETAR",IF(((AZ4="T")*AND(BA4="N")),"TOMADA",IF(((AZ4="P")*AND(BA4="N")*AND(BE4="N")),"PAINEL NORMAL",0))))))))))))))) -> PAINEL NORMAL | BD4: N | BE4: N | BF4: N | BG4: M | BH4: =IF(P4<=#REF!,#REF!,IF(P4<=#REF!,#REF!,IF(P4<=#REF!,#REF!,IF(P4<=#REF!,#REF!,IF(P4<=#REF!,#REF!,IF(P4<=#REF!,#REF!,IF(P4<=#REF!,#REF!,IF(P4<=#REF!,#REF!,IF(P4<=#REF!,#REF!,IF(P4<=#REF!,#REF!,IF(P4<=#REF!,#REF!,IF(P4<=#REF!,#REF!,IF(P4<=#REF!,#REF!,IF(P4<=#REF!,#REF!,IF(P4<=#REF!,#REF!,IF(P4<=#REF!,#REF!,IF(P4<=#REF!,#REF!,IF(P4<=#REF!,#REF!,IF(P4<=#REF!,#REF!,IF(P4<=#REF!,#REF!,IF(P4<=#REF!,#REF!,IF(P4<=#REF!,#REF!,IF(P4<=#REF!,#REF!,IF(P4<=#REF!,#REF!,0)))))))))))))))))))))))) -> #REF! | BI4: =IF(P4<=#REF!,#REF!,IF(P4<=#REF!,#REF!,IF(P4<=#REF!,#REF!,IF(P4<=#REF!,#REF!,IF(P4<=#REF!,#REF!,IF(P4<=#REF!,#REF!,IF(P4<=#REF!,#REF!,IF(P4<=#REF!,#REF!,IF(P4<=#REF!,#REF!,IF(P4<=#REF!,#REF!,IF(P4<=#REF!,#REF!,IF(P4<=#REF!,#REF!,IF(P4<=#REF!,#REF!,IF(P4<=#REF!,#REF!,IF(P4<=#REF!,#REF!,IF(P4<=#REF!,#REF!,IF(P4<=#REF!,#REF!,IF(P4<=#REF!,#REF!,IF(P4<=#REF!,#REF!,IF(P4<=#REF!,#REF!,IF(P4<=#REF!,#REF!,IF(P4<=#REF!,#REF!,IF(P4<=#REF!,#REF!,IF(P4<=#REF!,#REF!,0)))))))))))))))))))))))) -> #REF! | BJ4: 0.8
A5: 02 | B5: QDNO-397 | C5: - | D5: - | E5: BB | F5: 001 | G5: T | H5: PR | I5: QD-21012-0001 | J5: Sala de Pesagem - 0165.4.02 | K5: T1 - Balança de Bancada com Terminal de pesagem | L5: 60 | M5: kg | N5: =AX5 -> 220 | O5: 0.01 | P5: =AV5 -> 0.01 | Q5: =P5/V5/W5 -> 0.011764706 | R5: =P5*U5*X5 -> 0.007 | S5: =Q5*U5*X5 -> 0.0082352941 | T5: =AW5 -> 2 | U5: 1 | V5: =IF((BE5="N")*AND(BG5="M"),BJ5,BI5) -> 0.85 | W5: =IF(BE5="N",1,BH5/100) -> 1 | X5: 0.7 | Y5: =BB5 -> N | Z5: 24 | AA5: =Z5*R5 -> 0.168 | AB5: =AY5 -> NB | AC5: =IF((((T5=3))),(Q5*1000)/((SQRT(3)*N5)),(IF(((T5=1)),(Q5*1000)/((N5)),(IF(((T5=2)),(Q5*1000)/((N5)),0))))) -> 0.053475936 | AF5: =IF(AND($AX5=440,$AB5="-"),$S5," ") | AG5: =IF(AND($AX5=380,$AB5="-"),$S5," ") | AH5: =IF(AND($AX5=220,$AB5="-"),$S5," ") | AI5: =IF(AND($AX5=127,$AB5="-"),$S5," ") | AJ5: =IF(AND($AX5=440,$AB5="GE"),$S5," ") | AK5: =IF(AND($AX5=380,$AB5="GE"),$S5," ") | AL5: =IF(AND($AX5=220,$AB5="GE"),$S5," ") | AM5: =IF(AND($AX5=127,$AB5="GE"),$S5," ") | AN5: =IF(AND($AX5=440,$AB5="GE+NBL"),$S5," ") | AO5: =IF(AND($AX5=380,$AB5="GE+NBL"),$S5," ") | AP5: =IF(AND($AX5=220,$AB5="GE+NBL"),$S5," ") | AQ5: =IF(AND($AX5=127,$AB5="GE+NBL"),$S5," ") | AR5: =IF(AND($AX5=440,$AB5="GE+NB"),$S5," ") | AS5: =IF(AND($AX5=380,$AB5="GE+NB"),$S5," ") | AT5: =IF(AND($AX5=220,$AB5="GE+NB"),$S5," ") | AU5: =IF(AND($AX5=127,$AB5="GE+NB"),$S5," ") | AV5: 0.01 | AW5: 2 | AX5: 220 | AY5: NB | AZ5: T | BA5: N | BB5: N | BC5: =IF(((AZ5="P")*AND(BA5="N")*AND(BF5="S")*AND(BE5="S")*AND(BD5="N")*AND(AV5<=3.68)),"RELÉ",(IF(((AZ5="P")*AND(BA5="N")*AND(BE5="S")*AND(BD5="S")),"C-FORNECIDO",(IF(((AZ5="P")*AND(BA5="S")*AND(BD5="S")),"C-FORNECIDO",(IF(((AZ5="D")*AND(BA5="S")*AND(BD5="N")),"I-PROJETAR",(IF(((AZ5="P")*AND(BA5="N")*AND(BE5="S")*AND(AV5>=3.68)*AND(BD5="N")),"I-PROJETAR",(IF(((AZ5="D")*AND(BA5="N")*AND(BE5="S")*AND(AV5<=3.68)*AND(BD5="N")),"DIRETA",(IF(((AZ5="D")*AND(BA5="N")*AND(BE5="S")*AND(AV5>=3.68)*AND(BD5="N")),"I-PROJETAR",IF(((AZ5="T")*AND(BA5="N")),"TOMADA",IF(((AZ5="P")*AND(BA5="N")*AND(BE5="N")),"PAINEL NORMAL",0))))))))))))))) -> TOMADA | BD5: N | BE5: N | BF5: N | BG5: M | BH5: =IF(P5<=#REF!,#REF!,IF(P5<=#REF!,#REF!,IF(P5<=#REF!,#REF!,IF(P5<=#REF!,#REF!,IF(P5<=#REF!,#REF!,IF(P5<=#REF!,#REF!,IF(P5<=#REF!,#REF!,IF(P5<=#REF!,#REF!,IF(P5<=#REF!,#REF!,IF(P5<=#REF!,#REF!,IF(P5<=#REF!,#REF!,IF(P5<=#REF!,#REF!,IF(P5<=#REF!,#REF!,IF(P5<=#REF!,#REF!,IF(P5<=#REF!,#REF!,IF(P5<=#REF!,#REF!,IF(P5<=#REF!,#REF!,IF(P5<=#REF!,#REF!,IF(P5<=#REF!,#REF!,IF(P5<=#REF!,#REF!,IF(P5<=#REF!,#REF!,IF(P5<=#REF!,#REF!,IF(P5<=#REF!,#REF!,IF(P5<=#REF!,#REF!,0)))))))))))))))))))))))) -> #REF! | BI5: =IF(P5<=#REF!,#REF!,IF(P5<=#REF!,#REF!,IF(P5<=#REF!,#REF!,IF(P5<=#REF!,#REF!,IF(P5<=#REF!,#REF!,IF(P5<=#REF!,#REF!,IF(P5<=#REF!,#REF!,IF(P5<=#REF!,#REF!,IF(P5<=#REF!,#REF!,IF(P5<=#REF!,#REF!,IF(P5<=#REF!,#REF!,IF(P5<=#REF!,#REF!,IF(P5<=#REF!,#REF!,IF(P5<=#REF!,#REF!,IF(P5<=#REF!,#REF!,IF(P5<=#REF!,#REF!,IF(P5<=#REF!,#REF!,IF(P5<=#REF!,#REF!,IF(P5<=#REF!,#REF!,IF(P5<=#REF!,#REF!,IF(P5<=#REF!,#REF!,IF(P5<=#REF!,#REF!,IF(P5<=#REF!,#REF!,IF(P5<=#REF!,#REF!,0)))))))))))))))))))))))) -> #REF! | BJ5: 0.85
A6: 02 | B6: QDNO-398 | C6: - | D6: - | E6: BB | F6: 002 | G6: T | H6: PR | I6: QD-21012-0001 | J6: Sala de Pesagem - 0165.4.02 | K6: T2 - Balança de Bancada com Terminal de pesagem | L6: 6 | M6: kg | N6: =AX6 -> 220 | O6: 0.01 | P6: =AV6 -> 0.01 | Q6: =P6/V6/W6 -> 0.011764706 | R6: =P6*U6*X6 -> 0.007 | S6: =Q6*U6*X6 -> 0.0082352941 | T6: =AW6 -> 2 | U6: 1 | V6: =IF((BE6="N")*AND(BG6="M"),BJ6,BI6) -> 0.85 | W6: =IF(BE6="N",1,BH6/100) -> 1 | X6: 0.7 | Y6: =BB6 -> N | Z6: 24 | AA6: =Z6*R6 -> 0.168 | AB6: =AY6 -> NB | AC6: =IF((((T6=3))),(Q6*1000)/((SQRT(3)*N6)),(IF(((T6=1)),(Q6*1000)/((N6)),(IF(((T6=2)),(Q6*1000)/((N6)),0))))) -> 0.053475936 | AF6: =IF(AND($AX6=440,$AB6="-"),$S6," ") | AG6: =IF(AND($AX6=380,$AB6="-"),$S6," ") | AH6: =IF(AND($AX6=220,$AB6="-"),$S6," ") | AI6: =IF(AND($AX6=127,$AB6="-"),$S6," ") | AJ6: =IF(AND($AX6=440,$AB6="GE"),$S6," ") | AK6: =IF(AND($AX6=380,$AB6="GE"),$S6," ") | AL6: =IF(AND($AX6=220,$AB6="GE"),$S6," ") | AM6: =IF(AND($AX6=127,$AB6="GE"),$S6," ") | AN6: =IF(AND($AX6=440,$AB6="GE+NBL"),$S6," ") | AO6: =IF(AND($AX6=380,$AB6="GE+NBL"),$S6," ") | AP6: =IF(AND($AX6=220,$AB6="GE+NBL"),$S6," ") | AQ6: =IF(AND($AX6=127,$AB6="GE+NBL"),$S6," ") | AR6: =IF(AND($AX6=440,$AB6="GE+NB"),$S6," ") | AS6: =IF(AND($AX6=380,$AB6="GE+NB"),$S6," ") | AT6: =IF(AND($AX6=220,$AB6="GE+NB"),$S6," ") | AU6: =IF(AND($AX6=127,$AB6="GE+NB"),$S6," ") | AV6: 0.01 | AW6: 2 | AX6: 220 | AY6: NB | AZ6: T | BA6: N | BB6: N | BC6: =IF(((AZ6="P")*AND(BA6="N")*AND(BF6="S")*AND(BE6="S")*AND(BD6="N")*AND(AV6<=3.68)),"RELÉ",(IF(((AZ6="P")*AND(BA6="N")*AND(BE6="S")*AND(BD6="S")),"C-FORNECIDO",(IF(((AZ6="P")*AND(BA6="S")*AND(BD6="S")),"C-FORNECIDO",(IF(((AZ6="D")*AND(BA6="S")*AND(BD6="N")),"I-PROJETAR",(IF(((AZ6="P")*AND(BA6="N")*AND(BE6="S")*AND(AV6>=3.68)*AND(BD6="N")),"I-PROJETAR",(IF(((AZ6="D")*AND(BA6="N")*AND(BE6="S")*AND(AV6<=3.68)*AND(BD6="N")),"DIRETA",(IF(((AZ6="D")*AND(BA6="N")*AND(BE6="S")*AND(AV6>=3.68)*AND(BD6="N")),"I-PROJETAR",IF(((AZ6="T")*AND(BA6="N")),"TOMADA",IF(((AZ6="P")*AND(BA6="N")*AND(BE6="N")),"PAINEL NORMAL",0))))))))))))))) -> TOMADA | BD6: N | BE6: N | BF6: N | BG6: M | BH6: =IF(P6<=#REF!,#REF!,IF(P6<=#REF!,#REF!,IF(P6<=#REF!,#REF!,IF(P6<=#REF!,#REF!,IF(P6<=#REF!,#REF!,IF(P6<=#REF!,#REF!,IF(P6<=#REF!,#REF!,IF(P6<=#REF!,#REF!,IF(P6<=#REF!,#REF!,IF(P6<=#REF!,#REF!,IF(P6<=#REF!,#REF!,IF(P6<=#REF!,#REF!,IF(P6<=#REF!,#REF!,IF(P6<=#REF!,#REF!,IF(P6<=#REF!,#REF!,IF(P6<=#REF!,#REF!,IF(P6<=#REF!,#REF!,IF(P6<=#REF!,#REF!,IF(P6<=#REF!,#REF!,IF(P6<=#REF!,#REF!,IF(P6<=#REF!,#REF!,IF(P6<=#REF!,#REF!,IF(P6<=#REF!,#REF!,IF(P6<=#REF!,#REF!,0)))))))))))))))))))))))) -> #REF! | BI6: =IF(P6<=#REF!,#REF!,IF(P6<=#REF!,#REF!,IF(P6<=#REF!,#REF!,IF(P6<=#REF!,#REF!,IF(P6<=#REF!,#REF!,IF(P6<=#REF!,#REF!,IF(P6<=#REF!,#REF!,IF(P6<=#REF!,#REF!,IF(P6<=#REF!,#REF!,IF(P6<=#REF!,#REF!,IF(P6<=#REF!,#REF!,IF(P6<=#REF!,#REF!,IF(P6<=#REF!,#REF!,IF(P6<=#REF!,#REF!,IF(P6<=#REF!,#REF!,IF(P6<=#REF!,#REF!,IF(P6<=#REF!,#REF!,IF(P6<=#REF!,#REF!,IF(P6<=#REF!,#REF!,IF(P6<=#REF!,#REF!,IF(P6<=#REF!,#REF!,IF(P6<=#REF!,#REF!,IF(P6<=#REF!,#REF!,IF(P6<=#REF!,#REF!,0)))))))))))))))))))))))) -> #REF! | BJ6: 0.85
A7: 02 | B7: QDNO-399 | C7: - | D7: - | E7: IPS | F7: 001 | G7: T | H7: PR | I7: QD-21012-0001 | J7: Sala de Pesagem - 0165.4.02 | K7: T3 - Impressora de Etiquetas 01 | L7: - | M7: - | N7: =AX7 -> 220 | O7: 0.01 | P7: =AV7 -> 0.01 | Q7: =P7/V7/W7 -> 0.011764706 | R7: =P7*U7*X7 -> 0.007 | S7: =Q7*U7*X7 -> 0.0082352941 | T7: =AW7 -> 2 | U7: 1 | V7: =IF((BE7="N")*AND(BG7="M"),BJ7,BI7) -> 0.85 | W7: =IF(BE7="N",1,BH7/100) -> 1 | X7: 0.7 | Y7: =BB7 -> N | Z7: 24 | AA7: =Z7*R7 -> 0.168 | AB7: =AY7 -> NB | AC7: =IF((((T7=3))),(Q7*1000)/((SQRT(3)*N7)),(IF(((T7=1)),(Q7*1000)/((N7)),(IF(((T7=2)),(Q7*1000)/((N7)),0))))) -> 0.053475936 | AF7: =IF(AND($AX7=440,$AB7="-"),$S7," ") | AG7: =IF(AND($AX7=380,$AB7="-"),$S7," ") | AH7: =IF(AND($AX7=220,$AB7="-"),$S7," ") | AI7: =IF(AND($AX7=127,$AB7="-"),$S7," ") | AJ7: =IF(AND($AX7=440,$AB7="GE"),$S7," ") | AK7: =IF(AND($AX7=380,$AB7="GE"),$S7," ") | AL7: =IF(AND($AX7=220,$AB7="GE"),$S7," ") | AM7: =IF(AND($AX7=127,$AB7="GE"),$S7," ") | AN7: =IF(AND($AX7=440,$AB7="GE+NBL"),$S7," ") | AO7: =IF(AND($AX7=380,$AB7="GE+NBL"),$S7," ") | AP7: =IF(AND($AX7=220,$AB7="GE+NBL"),$S7," ") | AQ7: =IF(AND($AX7=127,$AB7="GE+NBL"),$S7," ") | AR7: =IF(AND($AX7=440,$AB7="GE+NB"),$S7," ") | AS7: =IF(AND($AX7=380,$AB7="GE+NB"),$S7," ") | AT7: =IF(AND($AX7=220,$AB7="GE+NB"),$S7," ") | AU7: =IF(AND($AX7=127,$AB7="GE+NB"),$S7," ") | AV7: 0.01 | AW7: 2 | AX7: 220 | AY7: NB | AZ7: T | BA7: N | BB7: N | BC7: =IF(((AZ7="P")*AND(BA7="N")*AND(BF7="S")*AND(BE7="S")*AND(BD7="N")*AND(AV7<=3.68)),"RELÉ",(IF(((AZ7="P")*AND(BA7="N")*AND(BE7="S")*AND(BD7="S")),"C-FORNECIDO",(IF(((AZ7="P")*AND(BA7="S")*AND(BD7="S")),"C-FORNECIDO",(IF(((AZ7="D")*AND(BA7="S")*AND(BD7="N")),"I-PROJETAR",(IF(((AZ7="P")*AND(BA7="N")*AND(BE7="S")*AND(AV7>=3.68)*AND(BD7="N")),"I-PROJETAR",(IF(((AZ7="D")*AND(BA7="N")*AND(BE7="S")*AND(AV7<=3.68)*AND(BD7="N")),"DIRETA",(IF(((AZ7="D")*AND(BA7="N")*AND(BE7="S")*AND(AV7>=3.68)*AND(BD7="N")),"I-PROJETAR",IF(((AZ7="T")*AND(BA7="N")),"TOMADA",IF(((AZ7="P")*AND(BA7="N")*AND(BE7="N")),"PAINEL NORMAL",0))))))))))))))) -> TOMADA | BD7: N | BE7: N | BF7: N | BG7: M | BH7: =IF(P7<=#REF!,#REF!,IF(P7<=#REF!,#REF!,IF(P7<=#REF!,#REF!,IF(P7<=#REF!,#REF!,IF(P7<=#REF!,#REF!,IF(P7<=#REF!,#REF!,IF(P7<=#REF!,#REF!,IF(P7<=#REF!,#REF!,IF(P7<=#REF!,#REF!,IF(P7<=#REF!,#REF!,IF(P7<=#REF!,#REF!,IF(P7<=#REF!,#REF!,IF(P7<=#REF!,#REF!,IF(P7<=#REF!,#REF!,IF(P7<=#REF!,#REF!,IF(P7<=#REF!,#REF!,IF(P7<=#REF!,#REF!,IF(P7<=#REF!,#REF!,IF(P7<=#REF!,#REF!,IF(P7<=#REF!,#REF!,IF(P7<=#REF!,#REF!,IF(P7<=#REF!,#REF!,IF(P7<=#REF!,#REF!,IF(P7<=#REF!,#REF!,0)))))))))))))))))))))))) -> #REF! | BI7: =IF(P7<=#REF!,#REF!,IF(P7<=#REF!,#REF!,IF(P7<=#REF!,#REF!,IF(P7<=#REF!,#REF!,IF(P7<=#REF!,#REF!,IF(P7<=#REF!,#REF!,IF(P7<=#REF!,#REF!,IF(P7<=#REF!,#REF!,IF(P7<=#REF!,#REF!,IF(P7<=#REF!,#REF!,IF(P7<=#REF!,#REF!,IF(P7<=#REF!,#REF!,IF(P7<=#REF!,#REF!,IF(P7<=#REF!,#REF!,IF(P7<=#REF!,#REF!,IF(P7<=#REF!,#REF!,IF(P7<=#REF!,#REF!,IF(P7<=#REF!,#REF!,IF(P7<=#REF!,#REF!,IF(P7<=#REF!,#REF!,IF(P7<=#REF!,#REF!,IF(P7<=#REF!,#REF!,IF(P7<=#REF!,#REF!,IF(P7<=#REF!,#REF!,0)))))))))))))))))))))))) -> #REF! | BJ7: 0.85
A8: 02 | B8: QDNO-400 | C8: - | D8: - | E8: IPS | F8: 002 | G8: T | H8: PR | I8: QD-21012-0001 | J8: Sala de Pesagem - 0165.4.02 | K8: T4 - Impressora de Etiquetas 02 | L8: - | M8: - | N8: =AX8 -> 220 | O8: 0.01 | P8: =AV8 -> 0.01 | Q8: =P8/V8/W8 -> 0.011764706 | R8: =P8*U8*X8 -> 0.007 | S8: =Q8*U8*X8 -> 0.0082352941 | T8: =AW8 -> 2 | U8: 1 | V8: =IF((BE8="N")*AND(BG8="M"),BJ8,BI8) -> 0.85 | W8: =IF(BE8="N",1,BH8/100) -> 1 | X8: 0.7 | Y8: =BB8 -> N | Z8: 24 | AA8: =Z8*R8 -> 0.168 | AB8: =AY8 -> NB | AC8: =IF((((T8=3))),(Q8*1000)/((SQRT(3)*N8)),(IF(((T8=1)),(Q8*1000)/((N8)),(IF(((T8=2)),(Q8*1000)/((N8)),0))))) -> 0.053475936 | AF8: =IF(AND($AX8=440,$AB8="-"),$S8," ") | AG8: =IF(AND($AX8=380,$AB8="-"),$S8," ") | AH8: =IF(AND($AX8=220,$AB8="-"),$S8," ") | AI8: =IF(AND($AX8=127,$AB8="-"),$S8," ") | AJ8: =IF(AND($AX8=440,$AB8="GE"),$S8," ") | AK8: =IF(AND($AX8=380,$AB8="GE"),$S8," ") | AL8: =IF(AND($AX8=220,$AB8="GE"),$S8," ") | AM8: =IF(AND($AX8=127,$AB8="GE"),$S8," ") | AN8: =IF(AND($AX8=440,$AB8="GE+NBL"),$S8," ") | AO8: =IF(AND($AX8=380,$AB8="GE+NBL"),$S8," ") | AP8: =IF(AND($AX8=220,$AB8="GE+NBL"),$S8," ") | AQ8: =IF(AND($AX8=127,$AB8="GE+NBL"),$S8," ") | AR8: =IF(AND($AX8=440,$AB8="GE+NB"),$S8," ") | AS8: =IF(AND($AX8=380,$AB8="GE+NB"),$S8," ") | AT8: =IF(AND($AX8=220,$AB8="GE+NB"),$S8," ") | AU8: =IF(AND($AX8=127,$AB8="GE+NB"),$S8," ") | AV8: 0.01 | AW8: 2 | AX8: 220 | AY8: NB | AZ8: T | BA8: N | BB8: N | BC8: =IF(((AZ8="P")*AND(BA8="N")*AND(BF8="S")*AND(BE8="S")*AND(BD8="N")*AND(AV8<=3.68)),"RELÉ",(IF(((AZ8="P")*AND(BA8="N")*AND(BE8="S")*AND(BD8="S")),"C-FORNECIDO",(IF(((AZ8="P")*AND(BA8="S")*AND(BD8="S")),"C-FORNECIDO",(IF(((AZ8="D")*AND(BA8="S")*AND(BD8="N")),"I-PROJETAR",(IF(((AZ8="P")*AND(BA8="N")*AND(BE8="S")*AND(AV8>=3.68)*AND(BD8="N")),"I-PROJETAR",(IF(((AZ8="D")*AND(BA8="N")*AND(BE8="S")*AND(AV8<=3.68)*AND(BD8="N")),"DIRETA",(IF(((AZ8="D")*AND(BA8="N")*AND(BE8="S")*AND(AV8>=3.68)*AND(BD8="N")),"I-PROJETAR",IF(((AZ8="T")*AND(BA8="N")),"TOMADA",IF(((AZ8="P")*AND(BA8="N")*AND(BE8="N")),"PAINEL NORMAL",0))))))))))))))) -> TOMADA | BD8: N | BE8: N | BF8: N | BG8: M | BH8: =IF(P8<=#REF!,#REF!,IF(P8<=#REF!,#REF!,IF(P8<=#REF!,#REF!,IF(P8<=#REF!,#REF!,IF(P8<=#REF!,#REF!,IF(P8<=#REF!,#REF!,IF(P8<=#REF!,#REF!,IF(P8<=#REF!,#REF!,IF(P8<=#REF!,#REF!,IF(P8<=#REF!,#REF!,IF(P8<=#REF!,#REF!,IF(P8<=#REF!,#REF!,IF(P8<=#REF!,#REF!,IF(P8<=#REF!,#REF!,IF(P8<=#REF!,#REF!,IF(P8<=#REF!,#REF!,IF(P8<=#REF!,#REF!,IF(P8<=#REF!,#REF!,IF(P8<=#REF!,#REF!,IF(P8<=#REF!,#REF!,IF(P8<=#REF!,#REF!,IF(P8<=#REF!,#REF!,IF(P8<=#REF!,#REF!,IF(P8<=#REF!,#REF!,0)))))))))))))))))))))))) -> #REF! | BI8: =IF(P8<=#REF!,#REF!,IF(P8<=#REF!,#REF!,IF(P8<=#REF!,#REF!,IF(P8<=#REF!,#REF!,IF(P8<=#REF!,#REF!,IF(P8<=#REF!,#REF!,IF(P8<=#REF!,#REF!,IF(P8<=#REF!,#REF!,IF(P8<=#REF!,#REF!,IF(P8<=#REF!,#REF!,IF(P8<=#REF!,#REF!,IF(P8<=#REF!,#REF!,IF(P8<=#REF!,#REF!,IF(P8<=#REF!,#REF!,IF(P8<=#REF!,#REF!,IF(P8<=#REF!,#REF!,IF(P8<=#REF!,#REF!,IF(P8<=#REF!,#REF!,IF(P8<=#REF!,#REF!,IF(P8<=#REF!,#REF!,IF(P8<=#REF!,#REF!,IF(P8<=#REF!,#REF!,IF(P8<=#REF!,#REF!,IF(P8<=#REF!,#REF!,0)))))))))))))))))))))))) -> #REF! | BJ8: 0.85
A9: 02 | C9: - | D9: - | E9: PAS | F9: 001 | G9: T | H9: PR | I9: QD-21012-0001 | J9: Sala de Entrada de Materiais - 0165.4.01 | K9: Pass Through Porta Guilhotina | N9: 220 | O9: 0.3 | P9: =AV9 -> 0.3 | Q9: =P9/V9/W9 -> 0.35294118 | R9: =P9*U9*X9 -> 0.21 | S9: =Q9*U9*X9 -> 0.24705882 | T9: =AW9 -> 2 | U9: 1 | V9: =IF((BE9="N")*AND(BG9="M"),BJ9,BI9) -> 0.85 | W9: =IF(BE9="N",1,BH9/100) -> 1 | X9: 0.7 | Y9: =BB9 -> N | Z9: 24 | AA9: =Z9*R9 -> 5.04 | AB9: =AY9 -> NB | AC9: =IF((((T9=3))),(Q9*1000)/((SQRT(3)*N9)),(IF(((T9=1)),(Q9*1000)/((N9)),(IF(((T9=2)),(Q9*1000)/((N9)),0))))) -> 1.6042781 | AF9: =IF(AND($AX9=440,$AB9="-"),$S9," ") | AG9: =IF(AND($AX9=380,$AB9="-"),$S9," ") | AH9: =IF(AND($AX9=220,$AB9="-"),$S9," ") | AI9: =IF(AND($AX9=127,$AB9="-"),$S9," ") | AJ9: =IF(AND($AX9=440,$AB9="GE"),$S9," ") | AK9: =IF(AND($AX9=380,$AB9="GE"),$S9," ") | AL9: =IF(AND($AX9=220,$AB9="GE"),$S9," ") | AM9: =IF(AND($AX9=127,$AB9="GE"),$S9," ") | AN9: =IF(AND($AX9=440,$AB9="GE+NBL"),$S9," ") | AO9: =IF(AND($AX9=380,$AB9="GE+NBL"),$S9," ") | AP9: =IF(AND($AX9=220,$AB9="GE+NBL"),$S9," ") | AQ9: =IF(AND($AX9=127,$AB9="GE+NBL"),$S9," ") | AR9: =IF(AND($AX9=440,$AB9="GE+NB"),$S9," ") | AS9: =IF(AND($AX9=380,$AB9="GE+NB"),$S9," ") | AT9: =IF(AND($AX9=220,$AB9="GE+NB"),$S9," ") | AU9: =IF(AND($AX9=127,$AB9="GE+NB"),$S9," ") | AV9: =O9 -> 0.3 | AW9: 2 | AX9: 220 | AY9: NB | AZ9: T | BA9: N | BB9: N | BC9: =IF(((AZ9="P")*AND(BA9="N")*AND(BF9="S")*AND(BE9="S")*AND(BD9="N")*AND(AV9<=3.68)),"RELÉ",(IF(((AZ9="P")*AND(BA9="N")*AND(BE9="S")*AND(BD9="S")),"C-FORNECIDO",(IF(((AZ9="P")*AND(BA9="S")*AND(BD9="S")),"C-FORNECIDO",(IF(((AZ9="D")*AND(BA9="S")*AND(BD9="N")),"I-PROJETAR",(IF(((AZ9="P")*AND(BA9="N")*AND(BE9="S")*AND(AV9>=3.68)*AND(BD9="N")),"I-PROJETAR",(IF(((AZ9="D")*AND(BA9="N")*AND(BE9="S")*AND(AV9<=3.68)*AND(BD9="N")),"DIRETA",(IF(((AZ9="D")*AND(BA9="N")*AND(BE9="S")*AND(AV9>=3.68)*AND(BD9="N")),"I-PROJETAR",IF(((AZ9="T")*AND(BA9="N")),"TOMADA",IF(((AZ9="P")*AND(BA9="N")*AND(BE9="N")),"PAINEL NORMAL",0))))))))))))))) -> TOMADA | BD9: N | BE9: N | BF9: N | BG9: M | BH9: =IF(P9<=#REF!,#REF!,IF(P9<=#REF!,#REF!,IF(P9<=#REF!,#REF!,IF(P9<=#REF!,#REF!,IF(P9<=#REF!,#REF!,IF(P9<=#REF!,#REF!,IF(P9<=#REF!,#REF!,IF(P9<=#REF!,#REF!,IF(P9<=#REF!,#REF!,IF(P9<=#REF!,#REF!,IF(P9<=#REF!,#REF!,IF(P9<=#REF!,#REF!,IF(P9<=#REF!,#REF!,IF(P9<=#REF!,#REF!,IF(P9<=#REF!,#REF!,IF(P9<=#REF!,#REF!,IF(P9<=#REF!,#REF!,IF(P9<=#REF!,#REF!,IF(P9<=#REF!,#REF!,IF(P9<=#REF!,#REF!,IF(P9<=#REF!,#REF!,IF(P9<=#REF!,#REF!,IF(P9<=#REF!,#REF!,IF(P9<=#REF!,#REF!,0)))))))))))))))))))))))) -> #REF! | BI9: =IF(P9<=#REF!,#REF!,IF(P9<=#REF!,#REF!,IF(P9<=#REF!,#REF!,IF(P9<=#REF!,#REF!,IF(P9<=#REF!,#REF!,IF(P9<=#REF!,#REF!,IF(P9<=#REF!,#REF!,IF(P9<=#REF!,#REF!,IF(P9<=#REF!,#REF!,IF(P9<=#REF!,#REF!,IF(P9<=#REF!,#REF!,IF(P9<=#REF!,#REF!,IF(P9<=#REF!,#REF!,IF(P9<=#REF!,#REF!,IF(P9<=#REF!,#REF!,IF(P9<=#REF!,#REF!,IF(P9<=#REF!,#REF!,IF(P9<=#REF!,#REF!,IF(P9<=#REF!,#REF!,IF(P9<=#REF!,#REF!,IF(P9<=#REF!,#REF!,IF(P9<=#REF!,#REF!,IF(P9<=#REF!,#REF!,IF(P9<=#REF!,#REF!,0)))))))))))))))))))))))) -> #REF! | BJ9: 0.85
A10: 02 | B10: QDNO-400 | C10: - | D10: - | E10: T1 | F10: 05 | G10: T | H10: PR | I10: QD-21012-0001 | J10: Sala de Pesagem - 0165.4.02 | K10: T5 - Disponível | L10: - | M10: - | N10: =AX10 -> 220 | O10: 1.87 | P10: =AV10 -> 1.87 | Q10: =P10/V10/W10 -> 2.2 | R10: =P10*U10*X10 -> 1.309 | S10: =Q10*U10*X10 -> 1.54 | T10: =AW10 -> 2 | U10: 1 | V10: =IF((BE10="N")*AND(BG10="M"),BJ10,BI10) -> 0.85 | W10: =IF(BE10="N",1,BH10/100) -> 1 | X10: 0.7 | Y10: =BB10 -> N | Z10: 24 | AA10: =Z10*R10 -> 31.416 | AB10: =AY10 -> NB | AC10: =IF((((T10=3))),(Q10*1000)/((SQRT(3)*N10)),(IF(((T10=1)),(Q10*1000)/((N10)),(IF(((T10=2)),(Q10*1000)/((N10)),0))))) -> 10 | AV10: 1.87 | AW10: 2 | AX10: 220 | AY10: NB | AZ10: T | BA10: N | BB10: N | BC10: =IF(((AZ10="P")*AND(BA10="N")*AND(BF10="S")*AND(BE10="S")*AND(BD10="N")*AND(AV10<=3.68)),"RELÉ",(IF(((AZ10="P")*AND(BA10="N")*AND(BE10="S")*AND(BD10="S")),"C-FORNECIDO",(IF(((AZ10="P")*AND(BA10="S")*AND(BD10="S")),"C-FORNECIDO",(IF(((AZ10="D")*AND(BA10="S")*AND(BD10="N")),"I-PROJETAR",(IF(((AZ10="P")*AND(BA10="N")*AND(BE10="S")*AND(AV10>=3.68)*AND(BD10="N")),"I-PROJETAR",(IF(((AZ10="D")*AND(BA10="N")*AND(BE10="S")*AND(AV10<=3.68)*AND(BD10="N")),"DIRETA",(IF(((AZ10="D")*AND(BA10="N")*AND(BE10="S")*AND(AV10>=3.68)*AND(BD10="N")),"I-PROJETAR",IF(((AZ10="T")*AND(BA10="N")),"TOMADA",IF(((AZ10="P")*AND(BA10="N")*AND(BE10="N")),"PAINEL NORMAL",0))))))))))))))) -> TOMADA | BD10: N | BE10: N | BF10: N | BG10: M | BH10: =IF(P10<=#REF!,#REF!,IF(P10<=#REF!,#REF!,IF(P10<=#REF!,#REF!,IF(P10<=#REF!,#REF!,IF(P10<=#REF!,#REF!,IF(P10<=#REF!,#REF!,IF(P10<=#REF!,#REF!,IF(P10<=#REF!,#REF!,IF(P10<=#REF!,#REF!,IF(P10<=#REF!,#REF!,IF(P10<=#REF!,#REF!,IF(P10<=#REF!,#REF!,IF(P10<=#REF!,#REF!,IF(P10<=#REF!,#REF!,IF(P10<=#REF!,#REF!,IF(P10<=#REF!,#REF!,IF(P10<=#REF!,#REF!,IF(P10<=#REF!,#REF!,IF(P10<=#REF!,#REF!,IF(P10<=#REF!,#REF!,IF(P10<=#REF!,#REF!,IF(P10<=#REF!,#REF!,IF(P10<=#REF!,#REF!,IF(P10<=#REF!,#REF!,0)))))))))))))))))))))))) -> #REF! | BI10: =IF(P10<=#REF!,#REF!,IF(P10<=#REF!,#REF!,IF(P10<=#REF!,#REF!,IF(P10<=#REF!,#REF!,IF(P10<=#REF!,#REF!,IF(P10<=#REF!,#REF!,IF(P10<=#REF!,#REF!,IF(P10<=#REF!,#REF!,IF(P10<=#REF!,#REF!,IF(P10<=#REF!,#REF!,IF(P10<=#REF!,#REF!,IF(P10<=#REF!,#REF!,IF(P10<=#REF!,#REF!,IF(P10<=#REF!,#REF!,IF(P10<=#REF!,#REF!,IF(P10<=#REF!,#REF!,IF(P10<=#REF!,#REF!,IF(P10<=#REF!,#REF!,IF(P10<=#REF!,#REF!,IF(P10<=#REF!,#REF!,IF(P10<=#REF!,#REF!,IF(P10<=#REF!,#REF!,IF(P10<=#REF!,#REF!,IF(P10<=#REF!,#REF!,0)))))))))))))))))))))))) -> #REF! | BJ10: 0.85
A11: 02 | B11: QDNO-400 | C11: - | D11: - | E11: T1 | F11: 06 | G11: T | H11: PR | I11: QD-21012-0001 | J11: Sala de Pesagem - 0165.4.02 | K11: T6 - Disponível | L11: - | M11: - | N11: =AX11 -> 220 | O11: 1.87 | P11: =AV11 -> 1.87 | Q11: =P11/V11/W11 -> 2.2 | R11: =P11*U11*X11 -> 1.309 | S11: =Q11*U11*X11 -> 1.54 | T11: =AW11 -> 2 | U11: 1 | V11: =IF((BE11="N")*AND(BG11="M"),BJ11,BI11) -> 0.85 | W11: =IF(BE11="N",1,BH11/100) -> 1 | X11: 0.7 | Y11: =BB11 -> N | Z11: 24 | AA11: =Z11*R11 -> 31.416 | AB11: =AY11 -> NB | AC11: =IF((((T11=3))),(Q11*1000)/((SQRT(3)*N11)),(IF(((T11=1)),(Q11*1000)/((N11)),(IF(((T11=2)),(Q11*1000)/((N11)),0))))) -> 10 | AV11: 1.87 | AW11: 2 | AX11: 220 | AY11: NB | AZ11: T | BA11: N | BB11: N | BC11: =IF(((AZ11="P")*AND(BA11="N")*AND(BF11="S")*AND(BE11="S")*AND(BD11="N")*AND(AV11<=3.68)),"RELÉ",(IF(((AZ11="P")*AND(BA11="N")*AND(BE11="S")*AND(BD11="S")),"C-FORNECIDO",(IF(((AZ11="P")*AND(BA11="S")*AND(BD11="S")),"C-FORNECIDO",(IF(((AZ11="D")*AND(BA11="S")*AND(BD11="N")),"I-PROJETAR",(IF(((AZ11="P")*AND(BA11="N")*AND(BE11="S")*AND(AV11>=3.68)*AND(BD11="N")),"I-PROJETAR",(IF(((AZ11="D")*AND(BA11="N")*AND(BE11="S")*AND(AV11<=3.68)*AND(BD11="N")),"DIRETA",(IF(((AZ11="D")*AND(BA11="N")*AND(BE11="S")*AND(AV11>=3.68)*AND(BD11="N")),"I-PROJETAR",IF(((AZ11="T")*AND(BA11="N")),"TOMADA",IF(((AZ11="P")*AND(BA11="N")*AND(BE11="N")),"PAINEL NORMAL",0))))))))))))))) -> TOMADA | BD11: N | BE11: N | BF11: N | BG11: M | BH11: =IF(P11<=#REF!,#REF!,IF(P11<=#REF!,#REF!,IF(P11<=#REF!,#REF!,IF(P11<=#REF!,#REF!,IF(P11<=#REF!,#REF!,IF(P11<=#REF!,#REF!,IF(P11<=#REF!,#REF!,IF(P11<=#REF!,#REF!,IF(P11<=#REF!,#REF!,IF(P11<=#REF!,#REF!,IF(P11<=#REF!,#REF!,IF(P11<=#REF!,#REF!,IF(P11<=#REF!,#REF!,IF(P11<=#REF!,#REF!,IF(P11<=#REF!,#REF!,IF(P11<=#REF!,#REF!,IF(P11<=#REF!,#REF!,IF(P11<=#REF!,#REF!,IF(P11<=#REF!,#REF!,IF(P11<=#REF!,#REF!,IF(P11<=#REF!,#REF!,IF(P11<=#REF!,#REF!,IF(P11<=#REF!,#REF!,IF(P11<=#REF!,#REF!,0)))))))))))))))))))))))) -> #REF! | BI11: =IF(P11<=#REF!,#REF!,IF(P11<=#REF!,#REF!,IF(P11<=#REF!,#REF!,IF(P11<=#REF!,#REF!,IF(P11<=#REF!,#REF!,IF(P11<=#REF!,#REF!,IF(P11<=#REF!,#REF!,IF(P11<=#REF!,#REF!,IF(P11<=#REF!,#REF!,IF(P11<=#REF!,#REF!,IF(P11<=#REF!,#REF!,IF(P11<=#REF!,#REF!,IF(P11<=#REF!,#REF!,IF(P11<=#REF!,#REF!,IF(P11<=#REF!,#REF!,IF(P11<=#REF!,#REF!,IF(P11<=#REF!,#REF!,IF(P11<=#REF!,#REF!,IF(P11<=#REF!,#REF!,IF(P11<=#REF!,#REF!,IF(P11<=#REF!,#REF!,IF(P11<=#REF!,#REF!,IF(P11<=#REF!,#REF!,IF(P11<=#REF!,#REF!,0)))))))))))))))))))))))) -> #REF! | BJ11: 0.85
A12: 02 | B12: QDNO-400 | C12: - | D12: PRI | E12: 150 | F12: 01 | G12: T | H12: AR | I12: QD-21012-0001 | J12: Antecâmara de Materiais - 0165.4.05 | K12: Porta Rápida Interna com Visor - Folha Simples de Enrolar (150x210cm) | N12: =AX12 -> 220 | O12: 1.5 | P12: =AV12 -> 1.5 | Q12: =P12/V12/W12 -> #REF! | R12: =P12*U12*X12 -> 1.05 | S12: =Q12*U12*X12 -> #REF! | T12: =AW12 -> 2 | U12: 1 | V12: =IF((BE12="N")*AND(BG12="M"),BJ12,BI12) -> #REF! | W12: =IF(BE12="N",1,BH12/100) -> #REF! | X12: 0.7 | Y12: =BB12 -> N | Z12: 24 | AA12: =Z12*R12 -> 25.2 | AB12: =AY12 -> NB | AC12: =IF((((T12=3))),(Q12*1000)/((SQRT(3)*N12)),(IF(((T12=1)),(Q12*1000)/((N12)),(IF(((T12=2)),(Q12*1000)/((N12)),0))))) -> #REF! | AV12: 1.5 | AW12: 2 | AX12: 220 | AY12: NB | AZ12: P | BA12: N | BB12: N | BC12: PAINEL NORMAL | BD12: N | BE12: S | BF12: N | BG12: A | BH12: =IF(P12<=#REF!,#REF!,IF(P12<=#REF!,#REF!,IF(P12<=#REF!,#REF!,IF(P12<=#REF!,#REF!,IF(P12<=#REF!,#REF!,IF(P12<=#REF!,#REF!,IF(P12<=#REF!,#REF!,IF(P12<=#REF!,#REF!,IF(P12<=#REF!,#REF!,IF(P12<=#REF!,#REF!,IF(P12<=#REF!,#REF!,IF(P12<=#REF!,#REF!,IF(P12<=#REF!,#REF!,IF(P12<=#REF!,#REF!,IF(P12<=#REF!,#REF!,IF(P12<=#REF!,#REF!,IF(P12<=#REF!,#REF!,IF(P12<=#REF!,#REF!,IF(P12<=#REF!,#REF!,IF(P12<=#REF!,#REF!,IF(P12<=#REF!,#REF!,IF(P12<=#REF!,#REF!,IF(P12<=#REF!,#REF!,IF(P12<=#REF!,#REF!,0)))))))))))))))))))))))) -> #REF! | BI12: =IF(P12<=#REF!,#REF!,IF(P12<=#REF!,#REF!,IF(P12<=#REF!,#REF!,IF(P12<=#REF!,#REF!,IF(P12<=#REF!,#REF!,IF(P12<=#REF!,#REF!,IF(P12<=#REF!,#REF!,IF(P12<=#REF!,#REF!,IF(P12<=#REF!,#REF!,IF(P12<=#REF!,#REF!,IF(P12<=#REF!,#REF!,IF(P12<=#REF!,#REF!,IF(P12<=#REF!,#REF!,IF(P12<=#REF!,#REF!,IF(P12<=#REF!,#REF!,IF(P12<=#REF!,#REF!,IF(P12<=#REF!,#REF!,IF(P12<=#REF!,#REF!,IF(P12<=#REF!,#REF!,IF(P12<=#REF!,#REF!,IF(P12<=#REF!,#REF!,IF(P12<=#REF!,#REF!,IF(P12<=#REF!,#REF!,IF(P12<=#REF!,#REF!,0)))))))))))))))))))))))) -> #REF! | BJ12: 0.85
A13: 02 | B13: QDNO-400 | C13: - | D13: PRI | E13: 150 | F13: 02 | G13: T | H13: AR | I13: QD-21012-0001 | J13: Antecâmara de Materiais - 0165.4.05 | K13: Porta Rápida Interna com Visor - Folha Simples de Enrolar (150x210cm) | N13: =AX13 -> 220 | O13: 1.5 | P13: =AV13 -> 1.5 | Q13: =P13/V13/W13 -> #REF! | R13: =P13*U13*X13 -> 1.05 | S13: =Q13*U13*X13 -> #REF! | T13: =AW13 -> 2 | U13: 1 | V13: =IF((BE13="N")*AND(BG13="M"),BJ13,BI13) -> #REF! | W13: =IF(BE13="N",1,BH13/100) -> #REF! | X13: 0.7 | Y13: =BB13 -> N | Z13: 24 | AA13: =Z13*R13 -> 25.2 | AB13: =AY13 -> NB | AC13: =IF((((T13=3))),(Q13*1000)/((SQRT(3)*N13)),(IF(((T13=1)),(Q13*1000)/((N13)),(IF(((T13=2)),(Q13*1000)/((N13)),0))))) -> #REF! | AV13: 1.5 | AW13: 2 | AX13: 220 | AY13: NB | AZ13: P | BA13: N | BB13: N | BC13: PAINEL NORMAL | BD13: N | BE13: S | BF13: N | BG13: A | BH13: =IF(P13<=#REF!,#REF!,IF(P13<=#REF!,#REF!,IF(P13<=#REF!,#REF!,IF(P13<=#REF!,#REF!,IF(P13<=#REF!,#REF!,IF(P13<=#REF!,#REF!,IF(P13<=#REF!,#REF!,IF(P13<=#REF!,#REF!,IF(P13<=#REF!,#REF!,IF(P13<=#REF!,#REF!,IF(P13<=#REF!,#REF!,IF(P13<=#REF!,#REF!,IF(P13<=#REF!,#REF!,IF(P13<=#REF!,#REF!,IF(P13<=#REF!,#REF!,IF(P13<=#REF!,#REF!,IF(P13<=#REF!,#REF!,IF(P13<=#REF!,#REF!,IF(P13<=#REF!,#REF!,IF(P13<=#REF!,#REF!,IF(P13<=#REF!,#REF!,IF(P13<=#REF!,#REF!,IF(P13<=#REF!,#REF!,IF(P13<=#REF!,#REF!,0)))))))))))))))))))))))) -> #REF! | BI13: =IF(P13<=#REF!,#REF!,IF(P13<=#REF!,#REF!,IF(P13<=#REF!,#REF!,IF(P13<=#REF!,#REF!,IF(P13<=#REF!,#REF!,IF(P13<=#REF!,#REF!,IF(P13<=#REF!,#REF!,IF(P13<=#REF!,#REF!,IF(P13<=#REF!,#REF!,IF(P13<=#REF!,#REF!,IF(P13<=#REF!,#REF!,IF(P13<=#REF!,#REF!,IF(P13<=#REF!,#REF!,IF(P13<=#REF!,#REF!,IF(P13<=#REF!,#REF!,IF(P13<=#REF!,#REF!,IF(P13<=#REF!,#REF!,IF(P13<=#REF!,#REF!,IF(P13<=#REF!,#REF!,IF(P13<=#REF!,#REF!,IF(P13<=#REF!,#REF!,IF(P13<=#REF!,#REF!,IF(P13<=#REF!,#REF!,IF(P13<=#REF!,#REF!,0)))))))))))))))))))))))) -> #REF! | BJ13: 0.85
A14: 02 | B14: QDNO-400 | C14: - | D14: PRI | E14: 150 | F14: 03 | G14: T | H14: AR | I14: QD-21012-0001 | J14: Antecâmara de Materiais - 0165.4.06 | K14: Porta Rápida Interna com Visor - Folha Simples de Enrolar (150x210cm) | N14: =AX14 -> 220 | O14: 1.5 | P14: =AV14 -> 1.5 | Q14: =P14/V14/W14 -> #REF! | R14: =P14*U14*X14 -> 1.05 | S14: =Q14*U14*X14 -> #REF! | T14: =AW14 -> 2 | U14: 1 | V14: =IF((BE14="N")*AND(BG14="M"),BJ14,BI14) -> #REF! | W14: =IF(BE14="N",1,BH14/100) -> #REF! | X14: 0.7 | Y14: =BB14 -> N | Z14: 24 | AA14: =Z14*R14 -> 25.2 | AB14: =AY14 -> NB | AC14: =IF((((T14=3))),(Q14*1000)/((SQRT(3)*N14)),(IF(((T14=1)),(Q14*1000)/((N14)),(IF(((T14=2)),(Q14*1000)/((N14)),0))))) -> #REF! | AV14: 1.5 | AW14: 2 | AX14: 220 | AY14: NB | AZ14: P | BA14: N | BB14: N | BC14: PAINEL NORMAL | BD14: N | BE14: S | BF14: N | BG14: A | BH14: =IF(P14<=#REF!,#REF!,IF(P14<=#REF!,#REF!,IF(P14<=#REF!,#REF!,IF(P14<=#REF!,#REF!,IF(P14<=#REF!,#REF!,IF(P14<=#REF!,#REF!,IF(P14<=#REF!,#REF!,IF(P14<=#REF!,#REF!,IF(P14<=#REF!,#REF!,IF(P14<=#REF!,#REF!,IF(P14<=#REF!,#REF!,IF(P14<=#REF!,#REF!,IF(P14<=#REF!,#REF!,IF(P14<=#REF!,#REF!,IF(P14<=#REF!,#REF!,IF(P14<=#REF!,#REF!,IF(P14<=#REF!,#REF!,IF(P14<=#REF!,#REF!,IF(P14<=#REF!,#REF!,IF(P14<=#REF!,#REF!,IF(P14<=#REF!,#REF!,IF(P14<=#REF!,#REF!,IF(P14<=#REF!,#REF!,IF(P14<=#REF!,#REF!,0)))))))))))))))))))))))) -> #REF! | BI14: =IF(P14<=#REF!,#REF!,IF(P14<=#REF!,#REF!,IF(P14<=#REF!,#REF!,IF(P14<=#REF!,#REF!,IF(P14<=#REF!,#REF!,IF(P14<=#REF!,#REF!,IF(P14<=#REF!,#REF!,IF(P14<=#REF!,#REF!,IF(P14<=#REF!,#REF!,IF(P14<=#REF!,#REF!,IF(P14<=#REF!,#REF!,IF(P14<=#REF!,#REF!,IF(P14<=#REF!,#REF!,IF(P14<=#REF!,#REF!,IF(P14<=#REF!,#REF!,IF(P14<=#REF!,#REF!,IF(P14<=#REF!,#REF!,IF(P14<=#REF!,#REF!,IF(P14<=#REF!,#REF!,IF(P14<=#REF!,#REF!,IF(P14<=#REF!,#REF!,IF(P14<=#REF!,#REF!,IF(P14<=#REF!,#REF!,IF(P14<=#REF!,#REF!,0)))))))))))))))))))))))) -> #REF! | BJ14: 0.85
A15: 02 | B15: QDNO-400 | C15: - | D15: PRI | E15: 180 | F15: 01 | G15: T | H15: AR | I15: QD-21012-0001 | J15: Antecâmara de Materiais - 0165.4.06 | K15: Porta Rápida Interna com Visor - Folha Simples de Enrolar (180x210cm) | N15: =AX15 -> 220 | O15: 1.5 | P15: =AV15 -> 1.5 | Q15: =P15/V15/W15 -> #REF! | R15: =P15*U15*X15 -> 1.05 | S15: =Q15*U15*X15 -> #REF! | T15: =AW15 -> 2 | U15: 1 | V15: =IF((BE15="N")*AND(BG15="M"),BJ15,BI15) -> #REF! | W15: =IF(BE15="N",1,BH15/100) -> #REF! | X15: 0.7 | Y15: =BB15 -> N | Z15: 24 | AA15: =Z15*R15 -> 25.2 | AB15: =AY15 -> NB | AC15: =IF((((T15=3))),(Q15*1000)/((SQRT(3)*N15)),(IF(((T15=1)),(Q15*1000)/((N15)),(IF(((T15=2)),(Q15*1000)/((N15)),0))))) -> #REF! | AV15: 1.5 | AW15: 2 | AX15: 220 | AY15: NB | AZ15: P | BA15: N | BB15: N | BC15: PAINEL NORMAL | BD15: N | BE15: S | BF15: N | BG15: A | BH15: =IF(P15<=#REF!,#REF!,IF(P15<=#REF!,#REF!,IF(P15<=#REF!,#REF!,IF(P15<=#REF!,#REF!,IF(P15<=#REF!,#REF!,IF(P15<=#REF!,#REF!,IF(P15<=#REF!,#REF!,IF(P15<=#REF!,#REF!,IF(P15<=#REF!,#REF!,IF(P15<=#REF!,#REF!,IF(P15<=#REF!,#REF!,IF(P15<=#REF!,#REF!,IF(P15<=#REF!,#REF!,IF(P15<=#REF!,#REF!,IF(P15<=#REF!,#REF!,IF(P15<=#REF!,#REF!,IF(P15<=#REF!,#REF!,IF(P15<=#REF!,#REF!,IF(P15<=#REF!,#REF!,IF(P15<=#REF!,#REF!,IF(P15<=#REF!,#REF!,IF(P15<=#REF!,#REF!,IF(P15<=#REF!,#REF!,IF(P15<=#REF!,#REF!,0)))))))))))))))))))))))) -> #REF! | BI15: =IF(P15<=#REF!,#REF!,IF(P15<=#REF!,#REF!,IF(P15<=#REF!,#REF!,IF(P15<=#REF!,#REF!,IF(P15<=#REF!,#REF!,IF(P15<=#REF!,#REF!,IF(P15<=#REF!,#REF!,IF(P15<=#REF!,#REF!,IF(P15<=#REF!,#REF!,IF(P15<=#REF!,#REF!,IF(P15<=#REF!,#REF!,IF(P15<=#REF!,#REF!,IF(P15<=#REF!,#REF!,IF(P15<=#REF!,#REF!,IF(P15<=#REF!,#REF!,IF(P15<=#REF!,#REF!,IF(P15<=#REF!,#REF!,IF(P15<=#REF!,#REF!,IF(P15<=#REF!,#REF!,IF(P15<=#REF!,#REF!,IF(P15<=#REF!,#REF!,IF(P15<=#REF!,#REF!,IF(P15<=#REF!,#REF!,IF(P15<=#REF!,#REF!,0)))))))))))))))))))))))) -> #REF! | BJ15: 0.85
A16: 02 | B16: QDNO-400 | C16: - | D16: - | E16: EQ | F16: 01 | G16: T | H16: AR | I16: QD-21012-0001 | J16: Antecâmara de Materiais - 0165.4.03 | K16: Armadilha Luminosa para Insetos (57x19x15cm) | N16: =AX16 -> 220 | O16: 0.03 | P16: =AV16 -> 0.03 | Q16: =P16/V16/W16 -> 0.035294118 | R16: =P16*U16*X16 -> 0.021 | S16: =Q16*U16*X16 -> 0.024705882 | T16: =AW16 -> 2 | U16: 1 | V16: =IF((BE16="N")*AND(BG16="M"),BJ16,BI16) -> 0.85 | W16: =IF(BE16="N",1,BH16/100) -> 1 | X16: 0.7 | Y16: =BB16 -> N | Z16: 24 | AA16: =Z16*R16 -> 0.504 | AB16: =AY16 -> NB | AC16: =IF((((T16=3))),(Q16*1000)/((SQRT(3)*N16)),(IF(((T16=1)),(Q16*1000)/((N16)),(IF(((T16=2)),(Q16*1000)/((N16)),0))))) -> 0.16042781 | AV16: 0.03 | AW16: 2 | AX16: 220 | AY16: NB | AZ16: T | BA16: N | BB16: N | BC16: =IF(((AZ16="P")*AND(BA16="N")*AND(BF16="S")*AND(BE16="S")*AND(BD16="N")*AND(AV16<=3.68)),"RELÉ",(IF(((AZ16="P")*AND(BA16="N")*AND(BE16="S")*AND(BD16="S")),"C-FORNECIDO",(IF(((AZ16="P")*AND(BA16="S")*AND(BD16="S")),"C-FORNECIDO",(IF(((AZ16="D")*AND(BA16="S")*AND(BD16="N")),"I-PROJETAR",(IF(((AZ16="P")*AND(BA16="N")*AND(BE16="S")*AND(AV16>=3.68)*AND(BD16="N")),"I-PROJETAR",(IF(((AZ16="D")*AND(BA16="N")*AND(BE16="S")*AND(AV16<=3.68)*AND(BD16="N")),"DIRETA",(IF(((AZ16="D")*AND(BA16="N")*AND(BE16="S")*AND(AV16>=3.68)*AND(BD16="N")),"I-PROJETAR",IF(((AZ16="T")*AND(BA16="N")),"TOMADA",IF(((AZ16="P")*AND(BA16="N")*AND(BE16="N")),"PAINEL NORMAL",0))))))))))))))) -> TOMADA | BD16: N | BE16: N | BF16: N | BG16: M | BH16: =IF(P16<=#REF!,#REF!,IF(P16<=#REF!,#REF!,IF(P16<=#REF!,#REF!,IF(P16<=#REF!,#REF!,IF(P16<=#REF!,#REF!,IF(P16<=#REF!,#REF!,IF(P16<=#REF!,#REF!,IF(P16<=#REF!,#REF!,IF(P16<=#REF!,#REF!,IF(P16<=#REF!,#REF!,IF(P16<=#REF!,#REF!,IF(P16<=#REF!,#REF!,IF(P16<=#REF!,#REF!,IF(P16<=#REF!,#REF!,IF(P16<=#REF!,#REF!,IF(P16<=#REF!,#REF!,IF(P16<=#REF!,#REF!,IF(P16<=#REF!,#REF!,IF(P16<=#REF!,#REF!,IF(P16<=#REF!,#REF!,IF(P16<=#REF!,#REF!,IF(P16<=#REF!,#REF!,IF(P16<=#REF!,#REF!,IF(P16<=#REF!,#REF!,0)))))))))))))))))))))))) -> #REF! | BI16: =IF(P16<=#REF!,#REF!,IF(P16<=#REF!,#REF!,IF(P16<=#REF!,#REF!,IF(P16<=#REF!,#REF!,IF(P16<=#REF!,#REF!,IF(P16<=#REF!,#REF!,IF(P16<=#REF!,#REF!,IF(P16<=#REF!,#REF!,IF(P16<=#REF!,#REF!,IF(P16<=#REF!,#REF!,IF(P16<=#REF!,#REF!,IF(P16<=#REF!,#REF!,IF(P16<=#REF!,#REF!,IF(P16<=#REF!,#REF!,IF(P16<=#REF!,#REF!,IF(P16<=#REF!,#REF!,IF(P16<=#REF!,#REF!,IF(P16<=#REF!,#REF!,IF(P16<=#REF!,#REF!,IF(P16<=#REF!,#REF!,IF(P16<=#REF!,#REF!,IF(P16<=#REF!,#REF!,IF(P16<=#REF!,#REF!,IF(P16<=#REF!,#REF!,0)))))))))))))))))))))))) -> #REF! | BJ16: 0.85
A17: 02 | B17: QDNO-405 | C17: - | D17: - | E17: - | F17: T | G17: 01 | H17: EL | I17: QD-21012-0001 | J17: Geral | K17: Tomadas de Uso Geral - 220V | L17: - | M17: - | N17: =AX17 -> 220 | O17: 1.8 | P17: =AV17 -> 1.8 | Q17: =P17/V17/W17 -> 2.195122 | R17: =P17*U17*X17 -> 1.26 | S17: =Q17*U17*X17 -> 1.5365854 | T17: =AW17 -> 2 | U17: 1 | V17: =IF((BE17="N")*AND(BG17="M"),BJ17,BI17) -> 0.82 | W17: =IF(BE17="N",1,BH17/100) -> 1 | X17: 0.7 | Y17: =BB17 -> N | Z17: 24 | AA17: =Z17*R17 -> 30.24 | AB17: NB | AC17: =IF((((T17=3))),(Q17*1000)/((SQRT(3)*N17)),(IF(((T17=1)),(Q17*1000)/((N17)),(IF(((T17=2)),(Q17*1000)/((N17)),0))))) -> 9.9778271 | AF17: =IF(AND($AX17=440,$AB17="-"),$S17," ") | AG17: =IF(AND($AX17=380,$AB17="-"),$S17," ") | AH17: =IF(AND($AX17=220,$AB17="-"),$S17," ") | AI17: =IF(AND($AX17=127,$AB17="-"),$S17," ") | AJ17: =IF(AND($AX17=440,$AB17="GE"),$S17," ") | AK17: =IF(AND($AX17=380,$AB17="GE"),$S17," ") | AL17: =IF(AND($AX17=220,$AB17="GE"),$S17," ") | AM17: =IF(AND($AX17=127,$AB17="GE"),$S17," ") | AN17: =IF(AND($AX17=440,$AB17="GE+NBL"),$S17," ") | AO17: =IF(AND($AX17=380,$AB17="GE+NBL"),$S17," ") | AP17: =IF(AND($AX17=220,$AB17="GE+NBL"),$S17," ") | AQ17: =IF(AND($AX17=127,$AB17="GE+NBL"),$S17," ") | AR17: =IF(AND($AX17=440,$AB17="GE+NB"),$S17," ") | AS17: =IF(AND($AX17=380,$AB17="GE+NB"),$S17," ") | AT17: =IF(AND($AX17=220,$AB17="GE+NB"),$S17," ") | AU17: =IF(AND($AX17=127,$AB17="GE+NB"),$S17," ") | AV17: 1.8 | AW17: 2 | AX17: 220 | AY17: - | AZ17: T | BA17: N | BB17: N | BC17: =IF(((AZ17="P")*AND(BA17="N")*AND(BF17="S")*AND(BE17="S")*AND(BD17="N")*AND(AV17<=3.68)),"RELÉ",(IF(((AZ17="P")*AND(BA17="N")*AND(BE17="S")*AND(BD17="S")),"C-FORNECIDO",(IF(((AZ17="P")*AND(BA17="S")*AND(BD17="S")),"C-FORNECIDO",(IF(((AZ17="D")*AND(BA17="S")*AND(BD17="N")),"I-PROJETAR",(IF(((AZ17="P")*AND(BA17="N")*AND(BE17="S")*AND(AV17>=3.68)*AND(BD17="N")),"I-PROJETAR",(IF(((AZ17="D")*AND(BA17="N")*AND(BE17="S")*AND(AV17<=3.68)*AND(BD17="N")),"DIRETA",(IF(((AZ17="D")*AND(BA17="N")*AND(BE17="S")*AND(AV17>=3.68)*AND(BD17="N")),"I-PROJETAR",IF(((AZ17="T")*AND(BA17="N")),"TOMADA",IF(((AZ17="P")*AND(BA17="N")*AND(BE17="N")),"PAINEL NORMAL",0))))))))))))))) -> TOMADA | BD17: N | BE17: N | BF17: N | BG17: M | BH17: =IF(P17<=#REF!,#REF!,IF(P17<=#REF!,#REF!,IF(P17<=#REF!,#REF!,IF(P17<=#REF!,#REF!,IF(P17<=#REF!,#REF!,IF(P17<=#REF!,#REF!,IF(P17<=#REF!,#REF!,IF(P17<=#REF!,#REF!,IF(P17<=#REF!,#REF!,IF(P17<=#REF!,#REF!,IF(P17<=#REF!,#REF!,IF(P17<=#REF!,#REF!,IF(P17<=#REF!,#REF!,IF(P17<=#REF!,#REF!,IF(P17<=#REF!,#REF!,IF(P17<=#REF!,#REF!,IF(P17<=#REF!,#REF!,IF(P17<=#REF!,#REF!,IF(P17<=#REF!,#REF!,IF(P17<=#REF!,#REF!,IF(P17<=#REF!,#REF!,IF(P17<=#REF!,#REF!,IF(P17<=#REF!,#REF!,IF(P17<=#REF!,#REF!,0)))))))))))))))))))))))) -> #REF! | BI17: =IF(P17<=#REF!,#REF!,IF(P17<=#REF!,#REF!,IF(P17<=#REF!,#REF!,IF(P17<=#REF!,#REF!,IF(P17<=#REF!,#REF!,IF(P17<=#REF!,#REF!,IF(P17<=#REF!,#REF!,IF(P17<=#REF!,#REF!,IF(P17<=#REF!,#REF!,IF(P17<=#REF!,#REF!,IF(P17<=#REF!,#REF!,IF(P17<=#REF!,#REF!,IF(P17<=#REF!,#REF!,IF(P17<=#REF!,#REF!,IF(P17<=#REF!,#REF!,IF(P17<=#REF!,#REF!,IF(P17<=#REF!,#REF!,IF(P17<=#REF!,#REF!,IF(P17<=#REF!,#REF!,IF(P17<=#REF!,#REF!,IF(P17<=#REF!,#REF!,IF(P17<=#REF!,#REF!,IF(P17<=#REF!,#REF!,IF(P17<=#REF!,#REF!,0)))))))))))))))))))))))) -> #REF! | BJ17: 0.82
A18: 02 | B18: QDNO-405 | C18: - | D18: - | E18: - | F18: IL | G18: 01 | H18: EL | I18: QDL-04 | J18: Geral | K18: Sistema de Iluminação | L18: - | M18: - | N18: =AX18 -> 220 | O18: 1.2 | P18: =AV18 -> 1.2 | Q18: =P18/V18/W18 -> 1.3333333 | R18: =P18*U18*X18 -> 1.2 | S18: =Q18*U18*X18 -> 1.3333333 | T18: =AW18 -> 2 | U18: 1 | V18: =IF((BE18="N")*AND(BG18="M"),BJ18,BI18) -> 0.9 | W18: =IF(BE18="N",1,BH18/100) -> 1 | X18: 1 | Y18: =BB18 -> N | Z18: 24 | AA18: =Z18*R18 -> 28.8 | AB18: =AY18 -> - | AC18: =IF((((T18=3))),(Q18*1000)/((SQRT(3)*N18)),(IF(((T18=1)),(Q18*1000)/((N18)),(IF(((T18=2)),(Q18*1000)/((N18)),0))))) -> 6.0606061 | AF18: =IF(AND($AX18=440,$AB18="-"),$S18," ") | AG18: =IF(AND($AX18=380,$AB18="-"),$S18," ") | AH18: =IF(AND($AX18=220,$AB18="-"),$S18," ") -> 1.3333333 | AI18: =IF(AND($AX18=127,$AB18="-"),$S18," ") | AJ18: =IF(AND($AX18=440,$AB18="GE"),$S18," ") | AK18: =IF(AND($AX18=380,$AB18="GE"),$S18," ") | AL18: =IF(AND($AX18=220,$AB18="GE"),$S18," ") | AM18: =IF(AND($AX18=127,$AB18="GE"),$S18," ") | AN18: =IF(AND($AX18=440,$AB18="GE+NBL"),$S18," ") | AO18: =IF(AND($AX18=380,$AB18="GE+NBL"),$S18," ") | AP18: =IF(AND($AX18=220,$AB18="GE+NBL"),$S18," ") | AQ18: =IF(AND($AX18=127,$AB18="GE+NBL"),$S18," ") | AR18: =IF(AND($AX18=440,$AB18="GE+NB"),$S18," ") | AS18: =IF(AND($AX18=380,$AB18="GE+NB"),$S18," ") | AT18: =IF(AND($AX18=220,$AB18="GE+NB"),$S18," ") | AU18: =IF(AND($AX18=127,$AB18="GE+NB"),$S18," ") | AV18: 1.2 | AW18: 2 | AX18: 220 | AY18: - | AZ18: T | BA18: N | BB18: N | BC18: =IF(((AZ18="P")*AND(BA18="N")*AND(BF18="S")*AND(BE18="S")*AND(BD18="N")*AND(AV18<=3.68)),"RELÉ",(IF(((AZ18="P")*AND(BA18="N")*AND(BE18="S")*AND(BD18="S")),"C-FORNECIDO",(IF(((AZ18="P")*AND(BA18="S")*AND(BD18="S")),"C-FORNECIDO",(IF(((AZ18="D")*AND(BA18="S")*AND(BD18="N")),"I-PROJETAR",(IF(((AZ18="P")*AND(BA18="N")*AND(BE18="S")*AND(AV18>=3.68)*AND(BD18="N")),"I-PROJETAR",(IF(((AZ18="D")*AND(BA18="N")*AND(BE18="S")*AND(AV18<=3.68)*AND(BD18="N")),"DIRETA",(IF(((AZ18="D")*AND(BA18="N")*AND(BE18="S")*AND(AV18>=3.68)*AND(BD18="N")),"I-PROJETAR",IF(((AZ18="T")*AND(BA18="N")),"TOMADA",IF(((AZ18="P")*AND(BA18="N")*AND(BE18="N")),"PAINEL NORMAL",0))))))))))))))) -> TOMADA | BD18: N | BE18: N | BF18: N | BG18: M | BH18: =IF(P18<=#REF!,#REF!,IF(P18<=#REF!,#REF!,IF(P18<=#REF!,#REF!,IF(P18<=#REF!,#REF!,IF(P18<=#REF!,#REF!,IF(P18<=#REF!,#REF!,IF(P18<=#REF!,#REF!,IF(P18<=#REF!,#REF!,IF(P18<=#REF!,#REF!,IF(P18<=#REF!,#REF!,IF(P18<=#REF!,#REF!,IF(P18<=#REF!,#REF!,IF(P18<=#REF!,#REF!,IF(P18<=#REF!,#REF!,IF(P18<=#REF!,#REF!,IF(P18<=#REF!,#REF!,IF(P18<=#REF!,#REF!,IF(P18<=#REF!,#REF!,IF(P18<=#REF!,#REF!,IF(P18<=#REF!,#REF!,IF(P18<=#REF!,#REF!,IF(P18<=#REF!,#REF!,IF(P18<=#REF!,#REF!,IF(P18<=#REF!,#REF!,0)))))))))))))))))))))))) -> #REF! | BI18: =IF(P18<=#REF!,#REF!,IF(P18<=#REF!,#REF!,IF(P18<=#REF!,#REF!,IF(P18<=#REF!,#REF!,IF(P18<=#REF!,#REF!,IF(P18<=#REF!,#REF!,IF(P18<=#REF!,#REF!,IF(P18<=#REF!,#REF!,IF(P18<=#REF!,#REF!,IF(P18<=#REF!,#REF!,IF(P18<=#REF!,#REF!,IF(P18<=#REF!,#REF!,IF(P18<=#REF!,#REF!,IF(P18<=#REF!,#REF!,IF(P18<=#REF!,#REF!,IF(P18<=#REF!,#REF!,IF(P18<=#REF!,#REF!,IF(P18<=#REF!,#REF!,IF(P18<=#REF!,#REF!,IF(P18<=#REF!,#REF!,IF(P18<=#REF!,#REF!,IF(P18<=#REF!,#REF!,IF(P18<=#REF!,#REF!,IF(P18<=#REF!,#REF!,0)))))))))))))))))))))))) -> #REF! | BJ18: 0.9
A19: TOTAL GERAL | O19: =SUM(O4:O18) -> 33.11 | P19: =SUM(P4:P18) -> 33.11 | Q19: =SUM(Q4:Q18) -> #REF! | R19: =SUM(R4:R18) -> 23.537 | S19: =SUM(S4:S18) -> #REF! | U19: - | V19: =P19/Q19 -> #REF! | W19: - | X19: =S19/Q19 -> #REF! | Y19: - | Z19: - | AA19: =SUM($AA$4:$AA$18) -> 564.888 | AF19: =SUM(AF4:AF18) -> 0 | AG19: =SUM(AG4:AG18) -> 0 | AH19: =SUM(AH4:AH18) -> 1.3333333 | AI19: =SUM(AI4:AI18) -> 0 | AJ19: =SUM(AJ4:AJ18) -> 0 | AK19: =SUM(AK4:AK18) -> 0 | AL19: =SUM(AL4:AL18) -> 0 | AM19: =SUM(AM4:AM18) -> 0 | ... AU19: =SUM(AU4:AU18) -> 0
K21: TOTAL 220V | O21: =SUMIFS(O$4:O$18,$N$4:$N$18,220) -> 13.11 | P21: =SUMIFS(P$4:P$18,$N$4:$N$18,220) -> 13.11 | Q21: =SUMIFS(Q$4:Q$18,$N$4:$N$18,220) -> #REF! | R21: =SUMIFS(R$4:R$18,$N$4:$N$18,220) -> 9.537 | S21: =SUMIFS(S$4:S$18,$N$4:$N$18,220) -> #REF!
K22: TOTAL 220V | O22: =SUMIFS(O$4:O$18,$N$4:$N$18,220) -> 13.11 | P22: =SUMIFS(P$4:P$18,$N$4:$N$18,220) -> 13.11 | Q22: =SUMIFS(Q$4:Q$18,$N$4:$N$18,220) -> #REF! | R22: =SUMIFS(R$4:R$18,$N$4:$N$18,220) -> 9.537 | S22: =SUMIFS(S$4:S$18,$N$4:$N$18,220) -> #REF!
K23: TOTAL 380V | O23: =SUMIFS(O$4:O$18,$N$4:$N$18,380) -> 0 | P23: =SUMIFS(P$4:P$18,$N$4:$N$18,380) -> 0 | Q23: =SUMIFS(Q$4:Q$18,$N$4:$N$18,380) -> 0 | R23: =SUMIFS(R$4:R$18,$N$4:$N$18,380) -> 0 | S23: =SUMIFS(S$4:S$18,$N$4:$N$18,380) -> 0
N27: PR | O27: =SUMIF($H$4:$H$18,$N27,O$4:O$18) -> 24.08 | P27: =SUMIF($H$4:$H$18,$N27,P$4:P$18) -> 24.08 | Q27: =SUMIF($H$4:$H$18,$N27,Q$4:Q$18) -> 29.8 | R27: =SUMIF($H$4:$H$18,$N27,R$4:R$18) -> 16.856 | S27: =SUMIF($H$4:$H$18,$N27,S$4:S$18) -> 20.86
N28: BU | O28: =SUMIF($H$4:$H$18,$N28,O$4:O$18) -> 0 | P28: =SUMIF($H$4:$H$18,$N28,P$4:P$18) -> 0 | Q28: =SUMIF($H$4:$H$18,$N28,Q$4:Q$18) -> 0 | R28: =SUMIF($H$4:$H$18,$N28,R$4:R$18) -> 0 | S28: =SUMIF($H$4:$H$18,$N28,S$4:S$18) -> 0
N29: CU | O29: =SUMIF($H$4:$H$18,$N29,O$4:O$18) -> 0 | P29: =SUMIF($H$4:$H$18,$N29,P$4:P$18) -> 0 | Q29: =SUMIF($H$4:$H$18,$N29,Q$4:Q$18) -> 0 | R29: =SUMIF($H$4:$H$18,$N29,R$4:R$18) -> 0 | S29: =SUMIF($H$4:$H$18,$N29,S$4:S$18) -> 0
N30: HA | O30: =SUMIF($H$4:$H$18,$N30,O$4:O$18) -> 0 | P30: =SUMIF($H$4:$H$18,$N30,P$4:P$18) -> 0 | Q30: =SUMIF($H$4:$H$18,$N30,Q$4:Q$18) -> 0 | R30: =SUMIF($H$4:$H$18,$N30,R$4:R$18) -> 0 | S30: =SUMIF($H$4:$H$18,$N30,S$4:S$18) -> 0
N31: AR | O31: =SUMIF($H$4:$H$18,$N31,O$4:O$18) -> 6.03 | P31: =SUMIF($H$4:$H$18,$N31,P$4:P$18) -> 6.03 | Q31: =SUMIF($H$4:$H$18,$N31,Q$4:Q$18) -> #REF! | R31: =SUMIF($H$4:$H$18,$N31,R$4:R$18) -> 4.221 | S31: =SUMIF($H$4:$H$18,$N31,S$4:S$18) -> #REF!
N32: EL | O32: =SUMIF($H$4:$H$18,$N32,O$4:O$18) -> 3 | P32: =SUMIF($H$4:$H$18,$N32,P$4:P$18) -> 3 | Q32: =SUMIF($H$4:$H$18,$N32,Q$4:Q$18) -> 3.5284553 | R32: =SUMIF($H$4:$H$18,$N32,R$4:R$18) -> 2.46 | S32: =SUMIF($H$4:$H$18,$N32,S$4:S$18) -> 2.8699187
N33: AT | O33: =SUMIF($H$4:$H$18,$N33,O$4:O$18) -> 0 | P33: =SUMIF($H$4:$H$18,$N33,P$4:P$18) -> 0 | Q33: =SUMIF($H$4:$H$18,$N33,Q$4:Q$18) -> 0 | R33: =SUMIF($H$4:$H$18,$N33,R$4:R$18) -> 0 | S33: =SUMIF($H$4:$H$18,$N33,S$4:S$18) -> 0
N34: TOTAL | O34: =SUM(O27:O33) -> 33.11 | P34: =SUM(P27:P33) -> 33.11 | Q34: =SUM(Q27:Q33) -> #REF! | R34: =SUM(R27:R33) -> 23.537 | S34: =SUM(S27:S33) -> #REF!
M38: QDL-301 | O38: =#REF!+#REF!+#REF! -> #REF! | P38: =#REF!+#REF!+#REF! -> #REF! | Q38: =#REF!+#REF!+#REF! -> #REF! | R38: =#REF!+#REF!+#REF! -> #REF! | S38: =#REF!+#REF!+#REF! -> #REF!
M39: QDNO-301 | O39: =O4+O5+O6+O7+O8+#REF!+#REF!+#REF!+#REF!+O18+O17+#REF!+#REF!+#REF!+#REF!+#REF!+#REF!+#REF!+#REF!+#REF!+#REF!+#REF!+#REF!+#REF!+#REF!+#REF!+#REF!+#REF!+#REF!+#REF!+#REF!+#REF!+#REF!+#REF!+#REF!+#REF!+#REF!+#REF!+#REF!+#REF!+#REF!+#REF!+#REF!+#REF!+#REF!+#REF!+#REF!+#REF!+#REF!+#REF!+#REF!+#REF!+#REF!+#REF!+#REF!+#REF!+#REF!+#REF!+#REF!+#REF!+#REF!+#REF!+#REF!+#REF!+#REF!+#REF!+#REF!+#REF!+#REF!+#REF!+#REF!+#REF!+#REF!+#REF!+#REF!+#REF!+#REF!+#REF!+#REF!+#REF!+#REF!+#REF!+#REF!+#REF!+#REF!+#REF!+#REF!+#REF!+#REF!+#REF!+#REF!+#REF!+#REF!+#REF!+#REF!+#REF!+#REF!+#REF!+#REF!+#REF!+#REF!+#REF!+#REF!+#REF!+#REF!+#REF!+#REF!+#REF!+#REF!+#REF!+#REF!+#REF!+#REF!+#REF!+#REF!+#REF!+#REF!+#REF!+#REF!+#REF!+#REF!+#REF!+#REF!+#REF!+#REF!+#REF!+#REF!+#REF!+#REF!+#REF!+#REF!+#REF!+#REF! -> #REF! | P39: =P4+P5+P6+P7+P8+#REF!+#REF!+#REF!+#REF!+P18+P17+#REF!+#REF!+#REF!+#REF!+#REF!+#REF!+#REF!+#REF!+#REF!+#REF!+#REF!+#REF!+#REF!+#REF!+#REF!+#REF!+#REF!+#REF!+#REF!+#REF!+#REF!+#REF!+#REF!+#REF!+#REF!+#REF!+#REF!+#REF!+#REF!+#REF!+#REF!+#REF!+#REF!+#REF!+#REF!+#REF!+#REF!+#REF!+#REF!+#REF!+#REF!+#REF!+#REF!+#REF!+#REF!+#REF!+#REF!+#REF!+#REF!+#REF!+#REF!+#REF!+#REF!+#REF!+#REF!+#REF!+#REF!+#REF!+#REF!+#REF!+#REF!+#REF!+#REF!+#REF!+#REF!+#REF!+#REF!+#REF!+#REF!+#REF!+#REF!+#REF!+#REF!+#REF!+#REF!+#REF!+#REF!+#REF!+#REF!+#REF!+#REF!+#REF!+#REF!+#REF!+#REF!+#REF!+#REF!+#REF!+#REF!+#REF!+#REF!+#REF!+#REF!+#REF!+#REF!+#REF!+#REF!+#REF!+#REF!+#REF!+#REF!+#REF!+#REF!+#REF!+#REF!+#REF!+#REF!+#REF!+#REF!+#REF!+#REF!+#REF!+#REF!+#REF!+#REF!+#REF!+#REF!+#REF!+#REF!+#REF!+#REF!+#REF! -> #REF! | Q39: =Q4+Q5+Q6+Q7+Q8+#REF!+#REF!+#REF!+#REF!+Q18+Q17+#REF!+#REF!+#REF!+#REF!+#REF!+#REF!+#REF!+#REF!+#REF!+#REF!+#REF!+#REF!+#REF!+#REF!+#REF!+#REF!+#REF!+#REF!+#REF!+#REF!+#REF!+#REF!+#REF!+#REF!+#REF!+#REF!+#REF!+#REF!+#REF!+#REF!+#REF!+#REF!+#REF!+#REF!+#REF!+#REF!+#REF!+#REF!+#REF!+#REF!+#REF!+#REF!+#REF!+#REF!+#REF!+#REF!+#REF!+#REF!+#REF!+#REF!+#REF!+#REF!+#REF!+#REF!+#REF!+#REF!+#REF!+#REF!+#REF!+#REF!+#REF!+#REF!+#REF!+#REF!+#REF!+#REF!+#REF!+#REF!+#REF!+#REF!+#REF!+#REF!+#REF!+#REF!+#REF!+#REF!+#REF!+#REF!+#REF!+#REF!+#REF!+#REF!+#REF!+#REF!+#REF!+#REF!+#REF!+#REF!+#REF!+#REF!+#REF!+#REF!+#REF!+#REF!+#REF!+#REF!+#REF!+#REF!+#REF!+#REF!+#REF!+#REF!+#REF!+#REF!+#REF!+#REF!+#REF!+#REF!+#REF!+#REF!+#REF!+#REF!+#REF!+#REF!+#REF!+#REF!+#REF!+#REF!+#REF!+#REF!+#REF!+#REF! -> #REF! | R39: =R4+R5+R6+R7+R8+#REF!+#REF!+#REF!+#REF!+R18+R17+#REF!+#REF!+#REF!+#REF!+#REF!+#REF!+#REF!+#REF!+#REF!+#REF!+#REF!+#REF!+#REF!+#REF!+#REF!+#REF!+#REF!+#REF!+#REF!+#REF!+#REF!+#REF!+#REF!+#REF!+#REF!+#REF!+#REF!+#REF!+#REF!+#REF!+#REF!+#REF!+#REF!+#REF!+#REF!+#REF!+#REF!+#REF!+#REF!+#REF!+#REF!+#REF!+#REF!+#REF!+#REF!+#REF!+#REF!+#REF!+#REF!+#REF!+#REF!+#REF!+#REF!+#REF!+#REF!+#REF!+#REF!+#REF!+#REF!+#REF!+#REF!+#REF!+#REF!+#REF!+#REF!+#REF!+#REF!+#REF!+#REF!+#REF!+#REF!+#REF!+#REF!+#REF!+#REF!+#REF!+#REF!+#REF!+#REF!+#REF!+#REF!+#REF!+#REF!+#REF!+#REF!+#REF!+#REF!+#REF!+#REF!+#REF!+#REF!+#REF!+#REF!+#REF!+#REF!+#REF!+#REF!+#REF!+#REF!+#REF!+#REF!+#REF!+#REF!+#REF!+#REF!+#REF!+#REF!+#REF!+#REF!+#REF!+#REF!+#REF!+#REF!+#REF!+#REF!+#REF!+#REF!+#REF!+#REF!+#REF!+#REF!+#REF! -> #REF! | S39: =S4+S5+S6+S7+S8+#REF!+#REF!+#REF!+#REF!+S18+S17+#REF!+#REF!+#REF!+#REF!+#REF!+#REF!+#REF!+#REF!+#REF!+#REF!+#REF!+#REF!+#REF!+#REF!+#REF!+#REF!+#REF!+#REF!+#REF!+#REF!+#REF!+#REF!+#REF!+#REF!+#REF!+#REF!+#REF!+#REF!+#REF!+#REF!+#REF!+#REF!+#REF!+#REF!+#REF!+#REF!+#REF!+#REF!+#REF!+#REF!+#REF!+#REF!+#REF!+#REF!+#REF!+#REF!+#REF!+#REF!+#REF!+#REF!+#REF!+#REF!+#REF!+#REF!+#REF!+#REF!+#REF!+#REF!+#REF!+#REF!+#REF!+#REF!+#REF!+#REF!+#REF!+#REF!+#REF!+#REF!+#REF!+#REF!+#REF!+#REF!+#REF!+#REF!+#REF!+#REF!+#REF!+#REF!+#REF!+#REF!+#REF!+#REF!+#REF!+#REF!+#REF!+#REF!+#REF!+#REF!+#REF!+#REF!+#REF!+#REF!+#REF!+#REF!+#REF!+#REF!+#REF!+#REF!+#REF!+#REF!+#REF!+#REF!+#REF!+#REF!+#REF!+#REF!+#REF!+#REF!+#REF!+#REF!+#REF!+#REF!+#REF!+#REF!+#REF!+#REF!+#REF!+#REF!+#REF!+#REF!+#REF!+#REF! -> #REF!
M40: QDF-396 | O40: =#REF!+#REF!+#REF!+#REF!+#REF!+#REF!+#REF!+#REF!+#REF!+#REF!+#REF!+#REF!+#REF!+#REF!+#REF!+#REF!+#REF!+#REF!+#REF!+#REF!+#REF!+#REF!+#REF!+#REF!+#REF!+#REF!+#REF!+#REF!+#REF!+#REF!+#REF!+#REF!+#REF!+#REF!+#REF!+#REF!+#REF!+#REF!+#REF!+#REF!+#REF!+#REF!+#REF!+#REF!+#REF!+#REF!+#REF!+#REF!+#REF!+#REF!+#REF!+#REF!+#REF!+#REF!+#REF!+#REF!+#REF!+#REF!+#REF!+#REF!+#REF!+#REF!+#REF!+#REF!+#REF!+#REF!+#REF!+#REF!+#REF!+#REF!+#REF!+#REF!+#REF!+#REF!+#REF!+#REF!+#REF!+#REF!+#REF!+#REF!+#REF!+#REF!+#REF!+#REF!+#REF!+#REF!+#REF!+#REF!+#REF!+#REF!+#REF!+#REF!+#REF!+#REF!+#REF!+#REF!+#REF!+#REF! -> #REF! | P40: =#REF!+#REF!+#REF!+#REF!+#REF!+#REF!+#REF!+#REF!+#REF!+#REF!+#REF!+#REF!+#REF!+#REF!+#REF!+#REF!+#REF!+#REF!+#REF!+#REF!+#REF!+#REF!+#REF!+#REF!+#REF!+#REF!+#REF!+#REF!+#REF!+#REF!+#REF!+#REF!+#REF!+#REF!+#REF!+#REF!+#REF!+#REF!+#REF!+#REF!+#REF!+#REF!+#REF!+#REF!+#REF!+#REF!+#REF!+#REF!+#REF!+#REF!+#REF!+#REF!+#REF!+#REF!+#REF!+#REF!+#REF!+#REF!+#REF!+#REF!+#REF!+#REF!+#REF!+#REF!+#REF!+#REF!+#REF!+#REF!+#REF!+#REF!+#REF!+#REF!+#REF!+#REF!+#REF!+#REF!+#REF!+#REF!+#REF!+#REF!+#REF!+#REF!+#REF!+#REF!+#REF!+#REF!+#REF!+#REF!+#REF!+#REF!+#REF!+#REF!+#REF!+#REF!+#REF!+#REF!+#REF!+#REF! -> #REF! | Q40: =#REF!+#REF!+#REF!+#REF!+#REF!+#REF!+#REF!+#REF!+#REF!+#REF!+#REF!+#REF!+#REF!+#REF!+#REF!+#REF!+#REF!+#REF!+#REF!+#REF!+#REF!+#REF!+#REF!+#REF!+#REF!+#REF!+#REF!+#REF!+#REF!+#REF!+#REF!+#REF!+#REF!+#REF!+#REF!+#REF!+#REF!+#REF!+#REF!+#REF!+#REF!+#REF!+#REF!+#REF!+#REF!+#REF!+#REF!+#REF!+#REF!+#REF!+#REF!+#REF!+#REF!+#REF!+#REF!+#REF!+#REF!+#REF!+#REF!+#REF!+#REF!+#REF!+#REF!+#REF!+#REF!+#REF!+#REF!+#REF!+#REF!+#REF!+#REF!+#REF!+#REF!+#REF!+#REF!+#REF!+#REF!+#REF!+#REF!+#REF!+#REF!+#REF!+#REF!+#REF!+#REF!+#REF!+#REF!+#REF!+#REF!+#REF!+#REF!+#REF!+#REF!+#REF!+#REF!+#REF!+#REF!+#REF! -> #REF! | R40: =#REF!+#REF!+#REF!+#REF!+#REF!+#REF!+#REF!+#REF!+#REF!+#REF!+#REF!+#REF!+#REF!+#REF!+#REF!+#REF!+#REF!+#REF!+#REF!+#REF!+#REF!+#REF!+#REF!+#REF!+#REF!+#REF!+#REF!+#REF!+#REF!+#REF!+#REF!+#REF!+#REF!+#REF!+#REF!+#REF!+#REF!+#REF!+#REF!+#REF!+#REF!+#REF!+#REF!+#REF!+#REF!+#REF!+#REF!+#REF!+#REF!+#REF!+#REF!+#REF!+#REF!+#REF!+#REF!+#REF!+#REF!+#REF!+#REF!+#REF!+#REF!+#REF!+#REF!+#REF!+#REF!+#REF!+#REF!+#REF!+#REF!+#REF!+#REF!+#REF!+#REF!+#REF!+#REF!+#REF!+#REF!+#REF!+#REF!+#REF!+#REF!+#REF!+#REF!+#REF!+#REF!+#REF!+#REF!+#REF!+#REF!+#REF!+#REF!+#REF!+#REF!+#REF!+#REF!+#REF!+#REF!+#REF! -> #REF! | S40: =#REF!+#REF!+#REF!+#REF!+#REF!+#REF!+#REF!+#REF!+#REF!+#REF!+#REF!+#REF!+#REF!+#REF!+#REF!+#REF!+#REF!+#REF!+#REF!+#REF!+#REF!+#REF!+#REF!+#REF!+#REF!+#REF!+#REF!+#REF!+#REF!+#REF!+#REF!+#REF!+#REF!+#REF!+#REF!+#REF!+#REF!+#REF!+#REF!+#REF!+#REF!+#REF!+#REF!+#REF!+#REF!+#REF!+#REF!+#REF!+#REF!+#REF!+#REF!+#REF!+#REF!+#REF!+#REF!+#REF!+#REF!+#REF!+#REF!+#REF!+#REF!+#REF!+#REF!+#REF!+#REF!+#REF!+#REF!+#REF!+#REF!+#REF!+#REF!+#REF!+#REF!+#REF!+#REF!+#REF!+#REF!+#REF!+#REF!+#REF!+#REF!+#REF!+#REF!+#REF!+#REF!+#REF!+#REF!+#REF!+#REF!+#REF!+#REF!+#REF!+#REF!+#REF!+#REF!+#REF!+#REF!+#REF! -> #REF!
M41: QDF-407 | O41: =#REF!+#REF!+#REF!+#REF!+#REF!+#REF!+#REF!+#REF!+#REF!+#REF!+#REF!+#REF!+#REF!+#REF!+#REF!+#REF!+#REF!+#REF!+#REF!+#REF! -> #REF! | P41: =#REF!+#REF!+#REF!+#REF!+#REF!+#REF!+#REF!+#REF!+#REF!+#REF!+#REF!+#REF!+#REF!+#REF!+#REF!+#REF!+#REF!+#REF!+#REF!+#REF! -> #REF! | Q41: =#REF!+#REF!+#REF!+#REF!+#REF!+#REF!+#REF!+#REF!+#REF!+#REF!+#REF!+#REF!+#REF!+#REF!+#REF!+#REF!+#REF!+#REF!+#REF!+#REF! -> #REF! | R41: =#REF!+#REF!+#REF!+#REF!+#REF!+#REF!+#REF!+#REF!+#REF!+#REF!+#REF!+#REF!+#REF!+#REF!+#REF!+#REF!+#REF!+#REF!+#REF!+#REF! -> #REF! | S41: =#REF!+#REF!+#REF!+#REF!+#REF!+#REF!+#REF!+#REF!+#REF!+#REF!+#REF!+#REF!+#REF!+#REF!+#REF!+#REF!+#REF!+#REF!+#REF!+#REF! -> #REF!
M42: QDF-302 | O42: =#REF! -> #REF! | P42: =#REF! -> #REF! | Q42: =#REF! -> #REF! | R42: =#REF! -> #REF! | S42: =#REF! -> #REF!

Sheet Lista de Carga
A1: LISTA DE CARGAS
A3: CLIENTE: FUNDAÇÃO HERMÍNIO OMETTO | U3: DATA: 10/05/2025
A4: PROJETO: PBC-001-25E-001 | U4: REVISÃO: 1
A7: INFORMAÇÕES COMPLEMENTARES | J7: TIPOS DE PARTIDA
A8: PAINEL DE MÉDIA TENSÃO: SE01-PMT-001 | J8: 1 - PARTIDA DIRETA COM RELÉ ELETRÔNICO DE SOBRECARGA.
A9: PAINEL DE BAIXA TENSÃO: QGBT-001 | J9: 2 - PARTIDA DIRETA COM CONTATOR
A10: TENSÃO CCM's E QUADROS: 380 V | J10: 3 - PARTIDA COM INVERSOR DE FREQUÊNCIA
A11: POTÊNCIA DO TRANSFORMADOR: 1000 kVA | J11: 4 - PARTIDA COM SOFT STARTER
A12: NÍVEL DE CURTO-CIRCUITO: 23.3 kA | J12: 5 - DISJUNTOR TERMOMAGNÉTICO (ALIMENTADOR)
J13: 6 - PARTIDA COM INVERSOR DE FREQUÊNCIA / REVERSÃO
J14: 7 - PARTIDA COM INVERSOR DE FREQUÊNCIA / REVERSÃO / FREIO
A16: ITEM | B16: PAINEL | C16: SISTEMA | D16: DESCRIÇÃO | E16: TAG | F16: TENSÃO | G16: Nº DE FASES | H16: TIPO DE PARTIDA | I16: POTÊNCIA (Hp) | J16: POTÊNCIA ATIVA NOMINAL (kW) | K16: POTÊNCIA ATIVA NOMINAL INSTALADA (kW) | L16: POTÊNCIA ATIVA CORRIGIDA (kW) | M16: POTÊNCIA REATIVA (kVAr) | N16: POTÊNCIA APARENTE (kVA) | O16: RENDIMENTO | P16: FATOR DE POTÊNCIA | Q16: CORRENTE NOMINAL (A) | R16: FATOR DE DEMANDA | S16: POTÊNCIA ATIVA DEMANDADA (kW) | T16: POTENCIA REATIVA DEMANDADA (kVAr) | U16: POTÊNCIA APARENTE DEMANDADA (kVA) | V16: CORRENTE NOMINAL DEMANDADA (A) | W16: DISPOSITIVO DE PROTEÇÃO (A) | X16: CONDUTOR | Y16: CARREGAMENTO (%) | Z16: OBSERVAÇÕES | AB16: FATOR DE UTILIZAÇÃO | AC16: EFICIÊNCIA
